Workbook
Name PERFORMANCETASKS: #REF!
Name PT: #REF!
Name QA: #REF!
Name QUARTERLYASSESSMENT: #REF!
Name SUBJECTS: '[1]INPUT DATA'!$A$1002:$A$1005
Name Transmu_Table: #REF!
Name WRITTENWORKS: #REF!
Name WW: #REF!

Sheet TERM 1
A1: Class Record
A3: (Pursuant to Deped Order 8 series of 2015)
F4: REGION | O4: DIVISION
F5: SCHOOL NAME | O5: SCHOOL ID | W5: SCHOOL YEAR
A7: FIRST TERM | F7: GRADE LEVEL AND SECTION | Q7: SUBJECT:
Q8: TEACHER:
A9: LEARNERS' NAMES | F9: WRITTEN/ ORAL WORKS (20%) | N9: PRODUCT/ PERFORMANCE TASKS (50%) | T9: SUMMATIVE TESTS/ TERM EXAMINATION (30%) | Z9: Initial Grade | AA9: Term Grade | AB9: Description
F10: 1 | G10: 2 | H10: 3 | I10: 4 | J10: 5 | K10: Total | L10: PS | M10: WS | N10: 1 | O10: 2 | P10: 3 | Q10: Total | R10: PS | S10: WS | T10: SA1 | U10: SA2 | V10: TE | W10: Total | X10: PS | Y10: WS
A11: HIGHEST POSSIBLE SCORE | K11: =IF(COUNT($F11:$J11)=0,"",SUM($F11:$J11)) | L11: 100 | M11: 0.2 | Q11: =IF(COUNT($N11:$P11)=0,"",SUM($N11:$P11)) | R11: 100 | S11: 0.5 | W11: =IF(COUNT($T11:$V11)=0,"",SUM($T11:$V11)) | X11: 100 | Y11: 0.3
A12: MALE
A13: 1 | K13: =IF(COUNT($F13:$J13)=0,"",SUM($F13:$J13)) | L13: =IFERROR(IF(K13="","",ROUND(K13/$K$11*100,2)),"") | M13: =IFERROR(IF(L13="","",ROUND(L13*$M$11,2)),"") | Q13: =IF(COUNT($N13:$P13)=0,"",SUM($N13:$P13)) | R13: =IFERROR(IF(Q13="","",ROUND(Q13/$Q$11*100,2)),"") | S13: =IFERROR(IF(R13="","",ROUND(R13*$S$11,2)),"") | W13: =IF(COUNT($T13:$V13)=0,"",SUM($T13:$V13)) | X13: =IFERROR(IF(W13="","",ROUND(W13/$W$11*100,2)),"") | Y13: =IFERROR(IF(X13="","",ROUND(X13*$Y$11,2)),"") | Z13: =IFERROR(M13+S13+Y13,"") | AA13: =IFERROR(VLOOKUP(Z13,#REF!,2,TRUE),"") | AB13: {=IF(AA13="", "", _xlfn.IFS(AA13>=90, "A", AA13>=80, "B", AA13>=75, "C", AA13>=65, "D", AA13>=0, "E"))}
A14: 2 | K14: =IF(COUNT($F14:$J14)=0,"",SUM($F14:$J14)) | L14: =IFERROR(IF(K14="","",ROUND(K14/$K$11*100,2)),"") | M14: =IFERROR(IF(L14="","",ROUND(L14*$M$11,2)),"") | Q14: =IF(COUNT($N14:$P14)=0,"",SUM($N14:$P14)) | R14: =IFERROR(IF(Q14="","",ROUND(Q14/$Q$11*100,2)),"") | S14: =IFERROR(IF(R14="","",ROUND(R14*$S$11,2)),"") | W14: =IF(COUNT($T14:$V14)=0,"",SUM($T14:$V14)) | X14: =IFERROR(IF(W14="","",ROUND(W14/$W$11*100,2)),"") | Y14: =IFERROR(IF(X14="","",ROUND(X14*$Y$11,2)),"") | Z14: =IFERROR(M14+S14+Y14,"") | AA14: =IFERROR(VLOOKUP(Z14,#REF!,2,TRUE),"") | AB14: {=IF(AA14="", "", _xlfn.IFS(AA14>=90, "A", AA14>=80, "B", AA14>=75, "C", AA14>=65, "D", AA14>=0, "E"))}
A15: 3 | K15: =IF(COUNT($F15:$J15)=0,"",SUM($F15:$J15)) | L15: =IFERROR(IF(K15="","",ROUND(K15/$K$11*100,2)),"") | M15: =IFERROR(IF(L15="","",ROUND(L15*$M$11,2)),"") | Q15: =IF(COUNT($N15:$P15)=0,"",SUM($N15:$P15)) | R15: =IFERROR(IF(Q15="","",ROUND(Q15/$Q$11*100,2)),"") | S15: =IFERROR(IF(R15="","",ROUND(R15*$S$11,2)),"") | W15: =IF(COUNT($T15:$V15)=0,"",SUM($T15:$V15)) | X15: =IFERROR(IF(W15="","",ROUND(W15/$W$11*100,2)),"") | Y15: =IFERROR(IF(X15="","",ROUND(X15*$Y$11,2)),"") | Z15: =IFERROR(M15+S15+Y15,"") | AA15: =IFERROR(VLOOKUP(Z15,#REF!,2,TRUE),"") | AB15: {=IF(AA15="", "", _xlfn.IFS(AA15>=90, "A", AA15>=80, "B", AA15>=75, "C", AA15>=65, "D", AA15>=0, "E"))}
A16: 4 | K16: =IF(COUNT($F16:$J16)=0,"",SUM($F16:$J16)) | L16: =IFERROR(IF(K16="","",ROUND(K16/$K$11*100,2)),"") | M16: =IFERROR(IF(L16="","",ROUND(L16*$M$11,2)),"") | Q16: =IF(COUNT($N16:$P16)=0,"",SUM($N16:$P16)) | R16: =IFERROR(IF(Q16="","",ROUND(Q16/$Q$11*100,2)),"") | S16: =IFERROR(IF(R16="","",ROUND(R16*$S$11,2)),"") | W16: =IF(COUNT($T16:$V16)=0,"",SUM($T16:$V16)) | X16: =IFERROR(IF(W16="","",ROUND(W16/$W$11*100,2)),"") | Y16: =IFERROR(IF(X16="","",ROUND(X16*$Y$11,2)),"") | Z16: =IFERROR(M16+S16+Y16,"") | AA16: =IFERROR(VLOOKUP(Z16,#REF!,2,TRUE),"") | AB16: {=IF(AA16="", "", _xlfn.IFS(AA16>=90, "A", AA16>=80, "B", AA16>=75, "C", AA16>=65, "D", AA16>=0, "E"))}
A17: 5 | K17: =IF(COUNT($F17:$J17)=0,"",SUM($F17:$J17)) | L17: =IFERROR(IF(K17="","",ROUND(K17/$K$11*100,2)),"") | M17: =IFERROR(IF(L17="","",ROUND(L17*$M$11,2)),"") | Q17: =IF(COUNT($N17:$P17)=0,"",SUM($N17:$P17)) | R17: =IFERROR(IF(Q17="","",ROUND(Q17/$Q$11*100,2)),"") | S17: =IFERROR(IF(R17="","",ROUND(R17*$S$11,2)),"") | W17: =IF(COUNT($T17:$V17)=0,"",SUM($T17:$V17)) | X17: =IFERROR(IF(W17="","",ROUND(W17/$W$11*100,2)),"") | Y17: =IFERROR(IF(X17="","",ROUND(X17*$Y$11,2)),"") | Z17: =IFERROR(M17+S17+Y17,"") | AA17: =IFERROR(VLOOKUP(Z17,#REF!,2,TRUE),"") | AB17: {=IF(AA17="", "", _xlfn.IFS(AA17>=90, "A", AA17>=80, "B", AA17>=75, "C", AA17>=65, "D", AA17>=0, "E"))}
A18: 6 | K18: =IF(COUNT($F18:$J18)=0,"",SUM($F18:$J18)) | L18: =IFERROR(IF(K18="","",ROUND(K18/$K$11*100,2)),"") | M18: =IFERROR(IF(L18="","",ROUND(L18*$M$11,2)),"") | Q18: =IF(COUNT($N18:$P18)=0,"",SUM($N18:$P18)) | R18: =IFERROR(IF(Q18="","",ROUND(Q18/$Q$11*100,2)),"") | S18: =IFERROR(IF(R18="","",ROUND(R18*$S$11,2)),"") | W18: =IF(COUNT($T18:$V18)=0,"",SUM($T18:$V18)) | X18: =IFERROR(IF(W18="","",ROUND(W18/$W$11*100,2)),"") | Y18: =IFERROR(IF(X18="","",ROUND(X18*$Y$11,2)),"") | Z18: =IFERROR(M18+S18+Y18,"") | AA18: =IFERROR(VLOOKUP(Z18,#REF!,2,TRUE),"") | AB18: {=IF(AA18="", "", _xlfn.IFS(AA18>=90, "A", AA18>=80, "B", AA18>=75, "C", AA18>=65, "D", AA18>=0, "E"))}
A19: 7 | K19: =IF(COUNT($F19:$J19)=0,"",SUM($F19:$J19)) | L19: =IFERROR(IF(K19="","",ROUND(K19/$K$11*100,2)),"") | M19: =IFERROR(IF(L19="","",ROUND(L19*$M$11,2)),"") | Q19: =IF(COUNT($N19:$P19)=0,"",SUM($N19:$P19)) | R19: =IFERROR(IF(Q19="","",ROUND(Q19/$Q$11*100,2)),"") | S19: =IFERROR(IF(R19="","",ROUND(R19*$S$11,2)),"") | W19: =IF(COUNT($T19:$V19)=0,"",SUM($T19:$V19)) | X19: =IFERROR(IF(W19="","",ROUND(W19/$W$11*100,2)),"") | Y19: =IFERROR(IF(X19="","",ROUND(X19*$Y$11,2)),"") | Z19: =IFERROR(M19+S19+Y19,"") | AA19: =IFERROR(VLOOKUP(Z19,#REF!,2,TRUE),"") | AB19: {=IF(AA19="", "", _xlfn.IFS(AA19>=90, "A", AA19>=80, "B", AA19>=75, "C", AA19>=65, "D", AA19>=0, "E"))}
A20: 8 | K20: =IF(COUNT($F20:$J20)=0,"",SUM($F20:$J20)) | L20: =IFERROR(IF(K20="","",ROUND(K20/$K$11*100,2)),"") | M20: =IFERROR(IF(L20="","",ROUND(L20*$M$11,2)),"") | Q20: =IF(COUNT($N20:$P20)=0,"",SUM($N20:$P20)) | R20: =IFERROR(IF(Q20="","",ROUND(Q20/$Q$11*100,2)),"") | S20: =IFERROR(IF(R20="","",ROUND(R20*$S$11,2)),"") | W20: =IF(COUNT($T20:$V20)=0,"",SUM($T20:$V20)) | X20: =IFERROR(IF(W20="","",ROUND(W20/$W$11*100,2)),"") | Y20: =IFERROR(IF(X20="","",ROUND(X20*$Y$11,2)),"") | Z20: =IFERROR(M20+S20+Y20,"") | AA20: =IFERROR(VLOOKUP(Z20,#REF!,2,TRUE),"") | AB20: {=IF(AA20="", "", _xlfn.IFS(AA20>=90, "A", AA20>=80, "B", AA20>=75, "C", AA20>=65, "D", AA20>=0, "E"))}
A21: 9 | K21: =IF(COUNT($F21:$J21)=0,"",SUM($F21:$J21)) | L21: =IFERROR(IF(K21="","",ROUND(K21/$K$11*100,2)),"") | M21: =IFERROR(IF(L21="","",ROUND(L21*$M$11,2)),"") | Q21: =IF(COUNT($N21:$P21)=0,"",SUM($N21:$P21)) | R21: =IFERROR(IF(Q21="","",ROUND(Q21/$Q$11*100,2)),"") | S21: =IFERROR(IF(R21="","",ROUND(R21*$S$11,2)),"") | W21: =IF(COUNT($T21:$V21)=0,"",SUM($T21:$V21)) | X21: =IFERROR(IF(W21="","",ROUND(W21/$W$11*100,2)),"") | Y21: =IFERROR(IF(X21="","",ROUND(X21*$Y$11,2)),"") | Z21: =IFERROR(M21+S21+Y21,"") | AA21: =IFERROR(VLOOKUP(Z21,#REF!,2,TRUE),"") | AB21: {=IF(AA21="", "", _xlfn.IFS(AA21>=90, "A", AA21>=80, "B", AA21>=75, "C", AA21>=65, "D", AA21>=0, "E"))}
A22: 10 | K22: =IF(COUNT($F22:$J22)=0,"",SUM($F22:$J22)) | L22: =IFERROR(IF(K22="","",ROUND(K22/$K$11*100,2)),"") | M22: =IFERROR(IF(L22="","",ROUND(L22*$M$11,2)),"") | Q22: =IF(COUNT($N22:$P22)=0,"",SUM($N22:$P22)) | R22: =IFERROR(IF(Q22="","",ROUND(Q22/$Q$11*100,2)),"") | S22: =IFERROR(IF(R22="","",ROUND(R22*$S$11,2)),"") | W22: =IF(COUNT($T22:$V22)=0,"",SUM($T22:$V22)) | X22: =IFERROR(IF(W22="","",ROUND(W22/$W$11*100,2)),"") | Y22: =IFERROR(IF(X22="","",ROUND(X22*$Y$11,2)),"") | Z22: =IFERROR(M22+S22+Y22,"") | AA22: =IFERROR(VLOOKUP(Z22,#REF!,2,TRUE),"") | AB22: {=IF(AA22="", "", _xlfn.IFS(AA22>=90, "A", AA22>=80, "B", AA22>=75, "C", AA22>=65, "D", AA22>=0, "E"))}
A23: 11 | K23: =IF(COUNT($F23:$J23)=0,"",SUM($F23:$J23)) | L23: =IFERROR(IF(K23="","",ROUND(K23/$K$11*100,2)),"") | M23: =IFERROR(IF(L23="","",ROUND(L23*$M$11,2)),"") | Q23: =IF(COUNT($N23:$P23)=0,"",SUM($N23:$P23)) | R23: =IFERROR(IF(Q23="","",ROUND(Q23/$Q$11*100,2)),"") | S23: =IFERROR(IF(R23="","",ROUND(R23*$S$11,2)),"") | W23: =IF(COUNT($T23:$V23)=0,"",SUM($T23:$V23)) | X23: =IFERROR(IF(W23="","",ROUND(W23/$W$11*100,2)),"") | Y23: =IFERROR(IF(X23="","",ROUND(X23*$Y$11,2)),"") | Z23: =IFERROR(M23+S23+Y23,"") | AA23: =IFERROR(VLOOKUP(Z23,#REF!,2,TRUE),"") | AB23: {=IF(AA23="", "", _xlfn.IFS(AA23>=90, "A", AA23>=80, "B", AA23>=75, "C", AA23>=65, "D", AA23>=0, "E"))}
A24: 12 | K24: =IF(COUNT($F24:$J24)=0,"",SUM($F24:$J24)) | L24: =IFERROR(IF(K24="","",ROUND(K24/$K$11*100,2)),"") | M24: =IFERROR(IF(L24="","",ROUND(L24*$M$11,2)),"") | Q24: =IF(COUNT($N24:$P24)=0,"",SUM($N24:$P24)) | R24: =IFERROR(IF(Q24="","",ROUND(Q24/$Q$11*100,2)),"") | S24: =IFERROR(IF(R24="","",ROUND(R24*$S$11,2)),"") | W24: =IF(COUNT($T24:$V24)=0,"",SUM($T24:$V24)) | X24: =IFERROR(IF(W24="","",ROUND(W24/$W$11*100,2)),"") | Y24: =IFERROR(IF(X24="","",ROUND(X24*$Y$11,2)),"") | Z24: =IFERROR(M24+S24+Y24,"") | AA24: =IFERROR(VLOOKUP(Z24,#REF!,2,TRUE),"") | AB24: {=IF(AA24="", "", _xlfn.IFS(AA24>=90, "A", AA24>=80, "B", AA24>=75, "C", AA24>=65, "D", AA24>=0, "E"))}
... A62: 50 | K62: =IF(COUNT($F62:$J62)=0,"",SUM($F62:$J62)) | L62: =IFERROR(IF(K62="","",ROUND(K62/$K$11*100,2)),"") | M62: =IFERROR(IF(L62="","",ROUND(L62*$M$11,2)),"") | Q62: =IF(COUNT($N62:$P62)=0,"",SUM($N62:$P62)) | R62: =IFERROR(IF(Q62="","",ROUND(Q62/$Q$11*100,2)),"") | S62: =IFERROR(IF(R62="","",ROUND(R62*$S$11,2)),"") | W62: =IF(COUNT($T62:$V62)=0,"",SUM($T62:$V62)) | X62: =IFERROR(IF(W62="","",ROUND(W62/$W$11*100,2)),"") | Y62: =IFERROR(IF(X62="","",ROUND(X62*$Y$11,2)),"") | Z62: =IFERROR(M62+S62+Y62,"") | AA62: =IFERROR(VLOOKUP(Z62,#REF!,2,TRUE),"") | AB62: {=IF(AA62="", "", _xlfn.IFS(AA62>=90, "A", AA62>=80, "B", AA62>=75, "C", AA62>=65, "D", AA62>=0, "E"))}
A63: FEMALE
A64: 1 | K64: =IF(COUNT($F64:$J64)=0,"",SUM($F64:$J64)) | L64: =IFERROR(IF(K64="","",ROUND(K64/$K$11*100,2)),"") | M64: =IFERROR(IF(L64="","",ROUND(L64*$M$11,2)),"") | Q64: =IF(COUNT($N64:$P64)=0,"",SUM($N64:$P64)) | R64: =IFERROR(IF(Q64="","",ROUND(Q64/$Q$11*100,2)),"") | S64: =IFERROR(IF(R64="","",ROUND(R64*$S$11,2)),"") | W64: =IF(COUNT($T64:$V64)=0,"",SUM($T64:$V64)) | X64: =IFERROR(IF(W64="","",ROUND(W64/$W$11*100,2)),"") | Y64: =IFERROR(IF(X64="","",ROUND(X64*$Y$11,2)),"") | Z64: =IFERROR(M64+S64+Y64,"") | AA64: =IFERROR(VLOOKUP(Z64,#REF!,2,TRUE),"") | AB64: {=IF(AA64="", "", _xlfn.IFS(AA64>=90, "A", AA64>=80, "B", AA64>=75, "C", AA64>=65, "D", AA64>=0, "E"))}
A65: 2 | K65: =IF(COUNT($F65:$J65)=0,"",SUM($F65:$J65)) | L65: =IFERROR(IF(K65="","",ROUND(K65/$K$11*100,2)),"") | M65: =IFERROR(IF(L65="","",ROUND(L65*$M$11,2)),"") | Q65: =IF(COUNT($N65:$P65)=0,"",SUM($N65:$P65)) | R65: =IFERROR(IF(Q65="","",ROUND(Q65/$Q$11*100,2)),"") | S65: =IFERROR(IF(R65="","",ROUND(R65*$S$11,2)),"") | W65: =IF(COUNT($T65:$V65)=0,"",SUM($T65:$V65)) | X65: =IFERROR(IF(W65="","",ROUND(W65/$W$11*100,2)),"") | Y65: =IFERROR(IF(X65="","",ROUND(X65*$Y$11,2)),"") | Z65: =IFERROR(M65+S65+Y65,"") | AA65: =IFERROR(VLOOKUP(Z65,#REF!,2,TRUE),"") | AB65: {=IF(AA65="", "", _xlfn.IFS(AA65>=90, "A", AA65>=80, "B", AA65>=75, "C", AA65>=65, "D", AA65>=0, "E"))}
A66: 3 | K66: =IF(COUNT($F66:$J66)=0,"",SUM($F66:$J66)) | L66: =IFERROR(IF(K66="","",ROUND(K66/$K$11*100,2)),"") | M66: =IFERROR(IF(L66="","",ROUND(L66*$M$11,2)),"") | Q66: =IF(COUNT($N66:$P66)=0,"",SUM($N66:$P66)) | R66: =IFERROR(IF(Q66="","",ROUND(Q66/$Q$11*100,2)),"") | S66: =IFERROR(IF(R66="","",ROUND(R66*$S$11,2)),"") | W66: =IF(COUNT($T66:$V66)=0,"",SUM($T66:$V66)) | X66: =IFERROR(IF(W66="","",ROUND(W66/$W$11*100,2)),"") | Y66: =IFERROR(IF(X66="","",ROUND(X66*$Y$11,2)),"") | Z66: =IFERROR(M66+S66+Y66,"") | AA66: =IFERROR(VLOOKUP(Z66,#REF!,2,TRUE),"") | AB66: {=IF(AA66="", "", _xlfn.IFS(AA66>=90, "A", AA66>=80, "B", AA66>=75, "C", AA66>=65, "D", AA66>=0, "E"))}
A67: 4 | K67: =IF(COUNT($F67:$J67)=0,"",SUM($F67:$J67)) | L67: =IFERROR(IF(K67="","",ROUND(K67/$K$11*100,2)),"") | M67: =IFERROR(IF(L67="","",ROUND(L67*$M$11,2)),"") | Q67: =IF(COUNT($N67:$P67)=0,"",SUM($N67:$P67)) | R67: =IFERROR(IF(Q67="","",ROUND(Q67/$Q$11*100,2)),"") | S67: =IFERROR(IF(R67="","",ROUND(R67*$S$11,2)),"") | W67: =IF(COUNT($T67:$V67)=0,"",SUM($T67:$V67)) | X67: =IFERROR(IF(W67="","",ROUND(W67/$W$11*100,2)),"") | Y67: =IFERROR(IF(X67="","",ROUND(X67*$Y$11,2)),"") | Z67: =IFERROR(M67+S67+Y67,"") | AA67: =IFERROR(VLOOKUP(Z67,#REF!,2,TRUE),"") | AB67: {=IF(AA67="", "", _xlfn.IFS(AA67>=90, "A", AA67>=80, "B", AA67>=75, "C", AA67>=65, "D", AA67>=0, "E"))}
A68: 5 | K68: =IF(COUNT($F68:$J68)=0,"",SUM($F68:$J68)) | L68: =IFERROR(IF(K68="","",ROUND(K68/$K$11*100,2)),"") | M68: =IFERROR(IF(L68="","",ROUND(L68*$M$11,2)),"") | Q68: =IF(COUNT($N68:$P68)=0,"",SUM($N68:$P68)) | R68: =IFERROR(IF(Q68="","",ROUND(Q68/$Q$11*100,2)),"") | S68: =IFERROR(IF(R68="","",ROUND(R68*$S$11,2)),"") | W68: =IF(COUNT($T68:$V68)=0,"",SUM($T68:$V68)) | X68: =IFERROR(IF(W68="","",ROUND(W68/$W$11*100,2)),"") | Y68: =IFERROR(IF(X68="","",ROUND(X68*$Y$11,2)),"") | Z68: =IFERROR(M68+S68+Y68,"") | AA68: =IFERROR(VLOOKUP(Z68,#REF!,2,TRUE),"") | AB68: {=IF(AA68="", "", _xlfn.IFS(AA68>=90, "A", AA68>=80, "B", AA68>=75, "C", AA68>=65, "D", AA68>=0, "E"))}
A69: 6 | K69: =IF(COUNT($F69:$J69)=0,"",SUM($F69:$J69)) | L69: =IFERROR(IF(K69="","",ROUND(K69/$K$11*100,2)),"") | M69: =IFERROR(IF(L69="","",ROUND(L69*$M$11,2)),"") | Q69: =IF(COUNT($N69:$P69)=0,"",SUM($N69:$P69)) | R69: =IFERROR(IF(Q69="","",ROUND(Q69/$Q$11*100,2)),"") | S69: =IFERROR(IF(R69="","",ROUND(R69*$S$11,2)),"") | W69: =IF(COUNT($T69:$V69)=0,"",SUM($T69:$V69)) | X69: =IFERROR(IF(W69="","",ROUND(W69/$W$11*100,2)),"") | Y69: =IFERROR(IF(X69="","",ROUND(X69*$Y$11,2)),"") | Z69: =IFERROR(M69+S69+Y69,"") | AA69: =IFERROR(VLOOKUP(Z69,#REF!,2,TRUE),"") | AB69: {=IF(AA69="", "", _xlfn.IFS(AA69>=90, "A", AA69>=80, "B", AA69>=75, "C", AA69>=65, "D", AA69>=0, "E"))}
A70: 7 | K70: =IF(COUNT($F70:$J70)=0,"",SUM($F70:$J70)) | L70: =IFERROR(IF(K70="","",ROUND(K70/$K$11*100,2)),"") | M70: =IFERROR(IF(L70="","",ROUND(L70*$M$11,2)),"") | Q70: =IF(COUNT($N70:$P70)=0,"",SUM($N70:$P70)) | R70: =IFERROR(IF(Q70="","",ROUND(Q70/$Q$11*100,2)),"") | S70: =IFERROR(IF(R70="","",ROUND(R70*$S$11,2)),"") | W70: =IF(COUNT($T70:$V70)=0,"",SUM($T70:$V70)) | X70: =IFERROR(IF(W70="","",ROUND(W70/$W$11*100,2)),"") | Y70: =IFERROR(IF(X70="","",ROUND(X70*$Y$11,2)),"") | Z70: =IFERROR(M70+S70+Y70,"") | AA70: =IFERROR(VLOOKUP(Z70,#REF!,2,TRUE),"") | AB70: {=IF(AA70="", "", _xlfn.IFS(AA70>=90, "A", AA70>=80, "B", AA70>=75, "C", AA70>=65, "D", AA70>=0, "E"))}
A71: 8 | K71: =IF(COUNT($F71:$J71)=0,"",SUM($F71:$J71)) | L71: =IFERROR(IF(K71="","",ROUND(K71/$K$11*100,2)),"") | M71: =IFERROR(IF(L71="","",ROUND(L71*$M$11,2)),"") | Q71: =IF(COUNT($N71:$P71)=0,"",SUM($N71:$P71)) | R71: =IFERROR(IF(Q71="","",ROUND(Q71/$Q$11*100,2)),"") | S71: =IFERROR(IF(R71="","",ROUND(R71*$S$11,2)),"") | W71: =IF(COUNT($T71:$V71)=0,"",SUM($T71:$V71)) | X71: =IFERROR(IF(W71="","",ROUND(W71/$W$11*100,2)),"") | Y71: =IFERROR(IF(X71="","",ROUND(X71*$Y$11,2)),"") | Z71: =IFERROR(M71+S71+Y71,"") | AA71: =IFERROR(VLOOKUP(Z71,#REF!,2,TRUE),"") | AB71: {=IF(AA71="", "", _xlfn.IFS(AA71>=90, "A", AA71>=80, "B", AA71>=75, "C", AA71>=65, "D", AA71>=0, "E"))}
A72: 9 | K72: =IF(COUNT($F72:$J72)=0,"",SUM($F72:$J72)) | L72: =IFERROR(IF(K72="","",ROUND(K72/$K$11*100,2)),"") | M72: =IFERROR(IF(L72="","",ROUND(L72*$M$11,2)),"") | Q72: =IF(COUNT($N72:$P72)=0,"",SUM($N72:$P72)) | R72: =IFERROR(IF(Q72="","",ROUND(Q72/$Q$11*100,2)),"") | S72: =IFERROR(IF(R72="","",ROUND(R72*$S$11,2)),"") | W72: =IF(COUNT($T72:$V72)=0,"",SUM($T72:$V72)) | X72: =IFERROR(IF(W72="","",ROUND(W72/$W$11*100,2)),"") | Y72: =IFERROR(IF(X72="","",ROUND(X72*$Y$11,2)),"") | Z72: =IFERROR(M72+S72+Y72,"") | AA72: =IFERROR(VLOOKUP(Z72,#REF!,2,TRUE),"") | AB72: {=IF(AA72="", "", _xlfn.IFS(AA72>=90, "A", AA72>=80, "B", AA72>=75, "C", AA72>=65, "D", AA72>=0, "E"))}
A73: 10 | K73: =IF(COUNT($F73:$J73)=0,"",SUM($F73:$J73)) | L73: =IFERROR(IF(K73="","",ROUND(K73/$K$11*100,2)),"") | M73: =IFERROR(IF(L73="","",ROUND(L73*$M$11,2)),"") | Q73: =IF(COUNT($N73:$P73)=0,"",SUM($N73:$P73)) | R73: =IFERROR(IF(Q73="","",ROUND(Q73/$Q$11*100,2)),"") | S73: =IFERROR(IF(R73="","",ROUND(R73*$S$11,2)),"") | W73: =IF(COUNT($T73:$V73)=0,"",SUM($T73:$V73)) | X73: =IFERROR(IF(W73="","",ROUND(W73/$W$11*100,2)),"") | Y73: =IFERROR(IF(X73="","",ROUND(X73*$Y$11,2)),"") | Z73: =IFERROR(M73+S73+Y73,"") | AA73: =IFERROR(VLOOKUP(Z73,#REF!,2,TRUE),"") | AB73: {=IF(AA73="", "", _xlfn.IFS(AA73>=90, "A", AA73>=80, "B", AA73>=75, "C", AA73>=65, "D", AA73>=0, "E"))}
A74: 11 | K74: =IF(COUNT($F74:$J74)=0,"",SUM($F74:$J74)) | L74: =IFERROR(IF(K74="","",ROUND(K74/$K$11*100,2)),"") | M74: =IFERROR(IF(L74="","",ROUND(L74*$M$11,2)),"") | Q74: =IF(COUNT($N74:$P74)=0,"",SUM($N74:$P74)) | R74: =IFERROR(IF(Q74="","",ROUND(Q74/$Q$11*100,2)),"") | S74: =IFERROR(IF(R74="","",ROUND(R74*$S$11,2)),"") | W74: =IF(COUNT($T74:$V74)=0,"",SUM($T74:$V74)) | X74: =IFERROR(IF(W74="","",ROUND(W74/$W$11*100,2)),"") | Y74: =IFERROR(IF(X74="","",ROUND(X74*$Y$11,2)),"") | Z74: =IFERROR(M74+S74+Y74,"") | AA74: =IFERROR(VLOOKUP(Z74,#REF!,2,TRUE),"") | AB74: {=IF(AA74="", "", _xlfn.IFS(AA74>=90, "A", AA74>=80, "B", AA74>=75, "C", AA74>=65, "D", AA74>=0, "E"))}
A75: 12 | K75: =IF(COUNT($F75:$J75)=0,"",SUM($F75:$J75)) | L75: =IFERROR(IF(K75="","",ROUND(K75/$K$11*100,2)),"") | M75: =IFERROR(IF(L75="","",ROUND(L75*$M$11,2)),"") | Q75: =IF(COUNT($N75:$P75)=0,"",SUM($N75:$P75)) | R75: =IFERROR(IF(Q75="","",ROUND(Q75/$Q$11*100,2)),"") | S75: =IFERROR(IF(R75="","",ROUND(R75*$S$11,2)),"") | W75: =IF(COUNT($T75:$V75)=0,"",SUM($T75:$V75)) | X75: =IFERROR(IF(W75="","",ROUND(W75/$W$11*100,2)),"") | Y75: =IFERROR(IF(X75="","",ROUND(X75*$Y$11,2)),"") | Z75: =IFERROR(M75+S75+Y75,"") | AA75: =IFERROR(VLOOKUP(Z75,#REF!,2,TRUE),"") | AB75: {=IF(AA75="", "", _xlfn.IFS(AA75>=90, "A", AA75>=80, "B", AA75>=75, "C", AA75>=65, "D", AA75>=0, "E"))}
... A113: 50 | K113: =IF(COUNT($F113:$J113)=0,"",SUM($F113:$J113)) | L113: =IFERROR(IF(K113="","",ROUND(K113/$K$11*100,2)),"") | M113: =IFERROR(IF(L113="","",ROUND(L113*$M$11,2)),"") | Q113: =IF(COUNT($N113:$P113)=0,"",SUM($N113:$P113)) | R113: =IFERROR(IF(Q113="","",ROUND(Q113/$Q$11*100,2)),"") | S113: =IFERROR(IF(R113="","",ROUND(R113*$S$11,2)),"") | W113: =IF(COUNT($T113:$V113)=0,"",SUM($T113:$V113)) | X113: =IFERROR(IF(W113="","",ROUND(W113/$W$11*100,2)),"") | Y113: =IFERROR(IF(X113="","",ROUND(X113*$Y$11,2)),"") | Z113: =IFERROR(M113+S113+Y113,"") | AA113: =IFERROR(VLOOKUP(Z113,#REF!,2,TRUE),"") | AB113: {=IF(AA113="", "", _xlfn.IFS(AA113>=90, "A", AA113>=80, "B", AA113>=75, "C", AA113>=65, "D", AA113>=0, "E"))}

Sheet TERM 2
A1: Class Record
A3: (Pursuant to Deped Order 8 series of 2015)
F4: REGION | O4: DIVISION
F5: SCHOOL NAME | O5: SCHOOL ID | W5: SCHOOL YEAR
A7: SECOND TERM | F7: GRADE LEVEL AND SECTION | Q7: SUBJECT:
Q8: TEACHER:
A9: LEARNERS' NAMES | F9: WRITTEN/ ORAL WORKS (20%) | N9: PRODUCT/ PERFORMANCE TASKS (50%) | T9: SUMMATIVE TESTS/ TERM EXAMINATION (30%) | Z9: Initial Grade | AA9: Term Grade | AB9: Description
F10: 1 | G10: 2 | H10: 3 | I10: 4 | J10: 5 | K10: Total | L10: PS | M10: WS | N10: 1 | O10: 2 | P10: 3 | Q10: Total | R10: PS | S10: WS | T10: SA1 | U10: SA2 | V10: TE | W10: Total | X10: PS | Y10: WS
A11: HIGHEST POSSIBLE SCORE | K11: =IF(COUNT($F11:$J11)=0,"",SUM($F11:$J11)) | L11: 100 | M11: 0.2 | Q11: =IF(COUNT($N11:$P11)=0,"",SUM($N11:$P11)) | R11: 100 | S11: 0.5 | W11: =IF(COUNT($T11:$V11)=0,"",SUM($T11:$V11)) | X11: 100 | Y11: 0.3
A12: MALE
A13: 1 | K13: =IF(COUNT($F13:$J13)=0,"",SUM($F13:$J13)) | L13: =IFERROR(IF(K13="","",ROUND(K13/$K$11*100,2)),"") | M13: =IFERROR(IF(L13="","",ROUND(L13*$M$11,2)),"") | Q13: =IF(COUNT($N13:$P13)=0,"",SUM($N13:$P13)) | R13: =IFERROR(IF(Q13="","",ROUND(Q13/$Q$11*100,2)),"") | S13: =IFERROR(IF(R13="","",ROUND(R13*$S$11,2)),"") | W13: =IF(COUNT($T13:$V13)=0,"",SUM($T13:$V13)) | X13: =IFERROR(IF(W13="","",ROUND(W13/$W$11*100,2)),"") | Y13: =IFERROR(IF(X13="","",ROUND(X13*$Y$11,2)),"") | Z13: =IFERROR(M13+S13+Y13,"") | AA13: =IFERROR(VLOOKUP(Z13,#REF!,2,TRUE),"") | AB13: {=IF(AA13="", "", _xlfn.IFS(AA13>=90, "A", AA13>=80, "B", AA13>=75, "C", AA13>=65, "D", AA13>=0, "E"))}
A14: 2 | K14: =IF(COUNT($F14:$J14)=0,"",SUM($F14:$J14)) | L14: =IFERROR(IF(K14="","",ROUND(K14/$K$11*100,2)),"") | M14: =IFERROR(IF(L14="","",ROUND(L14*$M$11,2)),"") | Q14: =IF(COUNT($N14:$P14)=0,"",SUM($N14:$P14)) | R14: =IFERROR(IF(Q14="","",ROUND(Q14/$Q$11*100,2)),"") | S14: =IFERROR(IF(R14="","",ROUND(R14*$S$11,2)),"") | W14: =IF(COUNT($T14:$V14)=0,"",SUM($T14:$V14)) | X14: =IFERROR(IF(W14="","",ROUND(W14/$W$11*100,2)),"") | Y14: =IFERROR(IF(X14="","",ROUND(X14*$Y$11,2)),"") | Z14: =IFERROR(M14+S14+Y14,"") | AA14: =IFERROR(VLOOKUP(Z14,#REF!,2,TRUE),"") | AB14: {=IF(AA14="", "", _xlfn.IFS(AA14>=90, "A", AA14>=80, "B", AA14>=75, "C", AA14>=65, "D", AA14>=0, "E"))}
A15: 3 | K15: =IF(COUNT($F15:$J15)=0,"",SUM($F15:$J15)) | L15: =IFERROR(IF(K15="","",ROUND(K15/$K$11*100,2)),"") | M15: =IFERROR(IF(L15="","",ROUND(L15*$M$11,2)),"") | Q15: =IF(COUNT($N15:$P15)=0,"",SUM($N15:$P15)) | R15: =IFERROR(IF(Q15="","",ROUND(Q15/$Q$11*100,2)),"") | S15: =IFERROR(IF(R15="","",ROUND(R15*$S$11,2)),"") | W15: =IF(COUNT($T15:$V15)=0,"",SUM($T15:$V15)) | X15: =IFERROR(IF(W15="","",ROUND(W15/$W$11*100,2)),"") | Y15: =IFERROR(IF(X15="","",ROUND(X15*$Y$11,2)),"") | Z15: =IFERROR(M15+S15+Y15,"") | AA15: =IFERROR(VLOOKUP(Z15,#REF!,2,TRUE),"") | AB15: {=IF(AA15="", "", _xlfn.IFS(AA15>=90, "A", AA15>=80, "B", AA15>=75, "C", AA15>=65, "D", AA15>=0, "E"))}
A16: 4 | K16: =IF(COUNT($F16:$J16)=0,"",SUM($F16:$J16)) | L16: =IFERROR(IF(K16="","",ROUND(K16/$K$11*100,2)),"") | M16: =IFERROR(IF(L16="","",ROUND(L16*$M$11,2)),"") | Q16: =IF(COUNT($N16:$P16)=0,"",SUM($N16:$P16)) | R16: =IFERROR(IF(Q16="","",ROUND(Q16/$Q$11*100,2)),"") | S16: =IFERROR(IF(R16="","",ROUND(R16*$S$11,2)),"") | W16: =IF(COUNT($T16:$V16)=0,"",SUM($T16:$V16)) | X16: =IFERROR(IF(W16="","",ROUND(W16/$W$11*100,2)),"") | Y16: =IFERROR(IF(X16="","",ROUND(X16*$Y$11,2)),"") | Z16: =IFERROR(M16+S16+Y16,"") | AA16: =IFERROR(VLOOKUP(Z16,#REF!,2,TRUE),"") | AB16: {=IF(AA16="", "", _xlfn.IFS(AA16>=90, "A", AA16>=80, "B", AA16>=75, "C", AA16>=65, "D", AA16>=0, "E"))}
A17: 5 | K17: =IF(COUNT($F17:$J17)=0,"",SUM($F17:$J17)) | L17: =IFERROR(IF(K17="","",ROUND(K17/$K$11*100,2)),"") | M17: =IFERROR(IF(L17="","",ROUND(L17*$M$11,2)),"") | Q17: =IF(COUNT($N17:$P17)=0,"",SUM($N17:$P17)) | R17: =IFERROR(IF(Q17="","",ROUND(Q17/$Q$11*100,2)),"") | S17: =IFERROR(IF(R17="","",ROUND(R17*$S$11,2)),"") | W17: =IF(COUNT($T17:$V17)=0,"",SUM($T17:$V17)) | X17: =IFERROR(IF(W17="","",ROUND(W17/$W$11*100,2)),"") | Y17: =IFERROR(IF(X17="","",ROUND(X17*$Y$11,2)),"") | Z17: =IFERROR(M17+S17+Y17,"") | AA17: =IFERROR(VLOOKUP(Z17,#REF!,2,TRUE),"") | AB17: {=IF(AA17="", "", _xlfn.IFS(AA17>=90, "A", AA17>=80, "B", AA17>=75, "C", AA17>=65, "D", AA17>=0, "E"))}
A18: 6 | K18: =IF(COUNT($F18:$J18)=0,"",SUM($F18:$J18)) | L18: =IFERROR(IF(K18="","",ROUND(K18/$K$11*100,2)),"") | M18: =IFERROR(IF(L18="","",ROUND(L18*$M$11,2)),"") | Q18: =IF(COUNT($N18:$P18)=0,"",SUM($N18:$P18)) | R18: =IFERROR(IF(Q18="","",ROUND(Q18/$Q$11*100,2)),"") | S18: =IFERROR(IF(R18="","",ROUND(R18*$S$11,2)),"") | W18: =IF(COUNT($T18:$V18)=0,"",SUM($T18:$V18)) | X18: =IFERROR(IF(W18="","",ROUND(W18/$W$11*100,2)),"") | Y18: =IFERROR(IF(X18="","",ROUND(X18*$Y$11,2)),"") | Z18: =IFERROR(M18+S18+Y18,"") | AA18: =IFERROR(VLOOKUP(Z18,#REF!,2,TRUE),"") | AB18: {=IF(AA18="", "", _xlfn.IFS(AA18>=90, "A", AA18>=80, "B", AA18>=75, "C", AA18>=65, "D", AA18>=0, "E"))}
A19: 7 | K19: =IF(COUNT($F19:$J19)=0,"",SUM($F19:$J19)) | L19: =IFERROR(IF(K19="","",ROUND(K19/$K$11*100,2)),"") | M19: =IFERROR(IF(L19="","",ROUND(L19*$M$11,2)),"") | Q19: =IF(COUNT($N19:$P19)=0,"",SUM($N19:$P19)) | R19: =IFERROR(IF(Q19="","",ROUND(Q19/$Q$11*100,2)),"") | S19: =IFERROR(IF(R19="","",ROUND(R19*$S$11,2)),"") | W19: =IF(COUNT($T19:$V19)=0,"",SUM($T19:$V19)) | X19: =IFERROR(IF(W19="","",ROUND(W19/$W$11*100,2)),"") | Y19: =IFERROR(IF(X19="","",ROUND(X19*$Y$11,2)),"") | Z19: =IFERROR(M19+S19+Y19,"") | AA19: =IFERROR(VLOOKUP(Z19,#REF!,2,TRUE),"") | AB19: {=IF(AA19="", "", _xlfn.IFS(AA19>=90, "A", AA19>=80, "B", AA19>=75, "C", AA19>=65, "D", AA19>=0, "E"))}
A20: 8 | K20: =IF(COUNT($F20:$J20)=0,"",SUM($F20:$J20)) | L20: =IFERROR(IF(K20="","",ROUND(K20/$K$11*100,2)),"") | M20: =IFERROR(IF(L20="","",ROUND(L20*$M$11,2)),"") | Q20: =IF(COUNT($N20:$P20)=0,"",SUM($N20:$P20)) | R20: =IFERROR(IF(Q20="","",ROUND(Q20/$Q$11*100,2)),"") | S20: =IFERROR(IF(R20="","",ROUND(R20*$S$11,2)),"") | W20: =IF(COUNT($T20:$V20)=0,"",SUM($T20:$V20)) | X20: =IFERROR(IF(W20="","",ROUND(W20/$W$11*100,2)),"") | Y20: =IFERROR(IF(X20="","",ROUND(X20*$Y$11,2)),"") | Z20: =IFERROR(M20+S20+Y20,"") | AA20: =IFERROR(VLOOKUP(Z20,#REF!,2,TRUE),"") | AB20: {=IF(AA20="", "", _xlfn.IFS(AA20>=90, "A", AA20>=80, "B", AA20>=75, "C", AA20>=65, "D", AA20>=0, "E"))}
A21: 9 | K21: =IF(COUNT($F21:$J21)=0,"",SUM($F21:$J21)) | L21: =IFERROR(IF(K21="","",ROUND(K21/$K$11*100,2)),"") | M21: =IFERROR(IF(L21="","",ROUND(L21*$M$11,2)),"") | Q21: =IF(COUNT($N21:$P21)=0,"",SUM($N21:$P21)) | R21: =IFERROR(IF(Q21="","",ROUND(Q21/$Q$11*100,2)),"") | S21: =IFERROR(IF(R21="","",ROUND(R21*$S$11,2)),"") | W21: =IF(COUNT($T21:$V21)=0,"",SUM($T21:$V21)) | X21: =IFERROR(IF(W21="","",ROUND(W21/$W$11*100,2)),"") | Y21: =IFERROR(IF(X21="","",ROUND(X21*$Y$11,2)),"") | Z21: =IFERROR(M21+S21+Y21,"") | AA21: =IFERROR(VLOOKUP(Z21,#REF!,2,TRUE),"") | AB21: {=IF(AA21="", "", _xlfn.IFS(AA21>=90, "A", AA21>=80, "B", AA21>=75, "C", AA21>=65, "D", AA21>=0, "E"))}
A22: 10 | K22: =IF(COUNT($F22:$J22)=0,"",SUM($F22:$J22)) | L22: =IFERROR(IF(K22="","",ROUND(K22/$K$11*100,2)),"") | M22: =IFERROR(IF(L22="","",ROUND(L22*$M$11,2)),"") | Q22: =IF(COUNT($N22:$P22)=0,"",SUM($N22:$P22)) | R22: =IFERROR(IF(Q22="","",ROUND(Q22/$Q$11*100,2)),"") | S22: =IFERROR(IF(R22="","",ROUND(R22*$S$11,2)),"") | W22: =IF(COUNT($T22:$V22)=0,"",SUM($T22:$V22)) | X22: =IFERROR(IF(W22="","",ROUND(W22/$W$11*100,2)),"") | Y22: =IFERROR(IF(X22="","",ROUND(X22*$Y$11,2)),"") | Z22: =IFERROR(M22+S22+Y22,"") | AA22: =IFERROR(VLOOKUP(Z22,#REF!,2,TRUE),"") | AB22: {=IF(AA22="", "", _xlfn.IFS(AA22>=90, "A", AA22>=80, "B", AA22>=75, "C", AA22>=65, "D", AA22>=0, "E"))}
A23: 11 | K23: =IF(COUNT($F23:$J23)=0,"",SUM($F23:$J23)) | L23: =IFERROR(IF(K23="","",ROUND(K23/$K$11*100,2)),"") | M23: =IFERROR(IF(L23="","",ROUND(L23*$M$11,2)),"") | Q23: =IF(COUNT($N23:$P23)=0,"",SUM($N23:$P23)) | R23: =IFERROR(IF(Q23="","",ROUND(Q23/$Q$11*100,2)),"") | S23: =IFERROR(IF(R23="","",ROUND(R23*$S$11,2)),"") | W23: =IF(COUNT($T23:$V23)=0,"",SUM($T23:$V23)) | X23: =IFERROR(IF(W23="","",ROUND(W23/$W$11*100,2)),"") | Y23: =IFERROR(IF(X23="","",ROUND(X23*$Y$11,2)),"") | Z23: =IFERROR(M23+S23+Y23,"") | AA23: =IFERROR(VLOOKUP(Z23,#REF!,2,TRUE),"") | AB23: {=IF(AA23="", "", _xlfn.IFS(AA23>=90, "A", AA23>=80, "B", AA23>=75, "C", AA23>=65, "D", AA23>=0, "E"))}
A24: 12 | K24: =IF(COUNT($F24:$J24)=0,"",SUM($F24:$J24)) | L24: =IFERROR(IF(K24="","",ROUND(K24/$K$11*100,2)),"") | M24: =IFERROR(IF(L24="","",ROUND(L24*$M$11,2)),"") | Q24: =IF(COUNT($N24:$P24)=0,"",SUM($N24:$P24)) | R24: =IFERROR(IF(Q24="","",ROUND(Q24/$Q$11*100,2)),"") | S24: =IFERROR(IF(R24="","",ROUND(R24*$S$11,2)),"") | W24: =IF(COUNT($T24:$V24)=0,"",SUM($T24:$V24)) | X24: =IFERROR(IF(W24="","",ROUND(W24/$W$11*100,2)),"") | Y24: =IFERROR(IF(X24="","",ROUND(X24*$Y$11,2)),"") | Z24: =IFERROR(M24+S24+Y24,"") | AA24: =IFERROR(VLOOKUP(Z24,#REF!,2,TRUE),"") | AB24: {=IF(AA24="", "", _xlfn.IFS(AA24>=90, "A", AA24>=80, "B", AA24>=75, "C", AA24>=65, "D", AA24>=0, "E"))}
... A62: 50 | K62: =IF(COUNT($F62:$J62)=0,"",SUM($F62:$J62)) | L62: =IFERROR(IF(K62="","",ROUND(K62/$K$11*100,2)),"") | M62: =IFERROR(IF(L62="","",ROUND(L62*$M$11,2)),"") | Q62: =IF(COUNT($N62:$P62)=0,"",SUM($N62:$P62)) | R62: =IFERROR(IF(Q62="","",ROUND(Q62/$Q$11*100,2)),"") | S62: =IFERROR(IF(R62="","",ROUND(R62*$S$11,2)),"") | W62: =IF(COUNT($T62:$V62)=0,"",SUM($T62:$V62)) | X62: =IFERROR(IF(W62="","",ROUND(W62/$W$11*100,2)),"") | Y62: =IFERROR(IF(X62="","",ROUND(X62*$Y$11,2)),"") | Z62: =IFERROR(M62+S62+Y62,"") | AA62: =IFERROR(VLOOKUP(Z62,#REF!,2,TRUE),"") | AB62: {=IF(AA62="", "", _xlfn.IFS(AA62>=90, "A", AA62>=80, "B", AA62>=75, "C", AA62>=65, "D", AA62>=0, "E"))}
A63: FEMALE
A64: 1 | K64: =IF(COUNT($F64:$J64)=0,"",SUM($F64:$J64)) | L64: =IFERROR(IF(K64="","",ROUND(K64/$K$11*100,2)),"") | M64: =IFERROR(IF(L64="","",ROUND(L64*$M$11,2)),"") | Q64: =IF(COUNT($N64:$P64)=0,"",SUM($N64:$P64)) | R64: =IFERROR(IF(Q64="","",ROUND(Q64/$Q$11*100,2)),"") | S64: =IFERROR(IF(R64="","",ROUND(R64*$S$11,2)),"") | W64: =IF(COUNT($T64:$V64)=0,"",SUM($T64:$V64)) | X64: =IFERROR(IF(W64="","",ROUND(W64/$W$11*100,2)),"") | Y64: =IFERROR(IF(X64="","",ROUND(X64*$Y$11,2)),"") | Z64: =IFERROR(M64+S64+Y64,"") | AA64: =IFERROR(VLOOKUP(Z64,#REF!,2,TRUE),"") | AB64: {=IF(AA64="", "", _xlfn.IFS(AA64>=90, "A", AA64>=80, "B", AA64>=75, "C", AA64>=65, "D", AA64>=0, "E"))}
A65: 2 | K65: =IF(COUNT($F65:$J65)=0,"",SUM($F65:$J65)) | L65: =IFERROR(IF(K65="","",ROUND(K65/$K$11*100,2)),"") | M65: =IFERROR(IF(L65="","",ROUND(L65*$M$11,2)),"") | Q65: =IF(COUNT($N65:$P65)=0,"",SUM($N65:$P65)) | R65: =IFERROR(IF(Q65="","",ROUND(Q65/$Q$11*100,2)),"") | S65: =IFERROR(IF(R65="","",ROUND(R65*$S$11,2)),"") | W65: =IF(COUNT($T65:$V65)=0,"",SUM($T65:$V65)) | X65: =IFERROR(IF(W65="","",ROUND(W65/$W$11*100,2)),"") | Y65: =IFERROR(IF(X65="","",ROUND(X65*$Y$11,2)),"") | Z65: =IFERROR(M65+S65+Y65,"") | AA65: =IFERROR(VLOOKUP(Z65,#REF!,2,TRUE),"") | AB65: {=IF(AA65="", "", _xlfn.IFS(AA65>=90, "A", AA65>=80, "B", AA65>=75, "C", AA65>=65, "D", AA65>=0, "E"))}
A66: 3 | K66: =IF(COUNT($F66:$J66)=0,"",SUM($F66:$J66)) | L66: =IFERROR(IF(K66="","",ROUND(K66/$K$11*100,2)),"") | M66: =IFERROR(IF(L66="","",ROUND(L66*$M$11,2)),"") | Q66: =IF(COUNT($N66:$P66)=0,"",SUM($N66:$P66)) | R66: =IFERROR(IF(Q66="","",ROUND(Q66/$Q$11*100,2)),"") | S66: =IFERROR(IF(R66="","",ROUND(R66*$S$11,2)),"") | W66: =IF(COUNT($T66:$V66)=0,"",SUM($T66:$V66)) | X66: =IFERROR(IF(W66="","",ROUND(W66/$W$11*100,2)),"") | Y66: =IFERROR(IF(X66="","",ROUND(X66*$Y$11,2)),"") | Z66: =IFERROR(M66+S66+Y66,"") | AA66: =IFERROR(VLOOKUP(Z66,#REF!,2,TRUE),"") | AB66: {=IF(AA66="", "", _xlfn.IFS(AA66>=90, "A", AA66>=80, "B", AA66>=75, "C", AA66>=65, "D", AA66>=0, "E"))}
A67: 4 | K67: =IF(COUNT($F67:$J67)=0,"",SUM($F67:$J67)) | L67: =IFERROR(IF(K67="","",ROUND(K67/$K$11*100,2)),"") | M67: =IFERROR(IF(L67="","",ROUND(L67*$M$11,2)),"") | Q67: =IF(COUNT($N67:$P67)=0,"",SUM($N67:$P67)) | R67: =IFERROR(IF(Q67="","",ROUND(Q67/$Q$11*100,2)),"") | S67: =IFERROR(IF(R67="","",ROUND(R67*$S$11,2)),"") | W67: =IF(COUNT($T67:$V67)=0,"",SUM($T67:$V67)) | X67: =IFERROR(IF(W67="","",ROUND(W67/$W$11*100,2)),"") | Y67: =IFERROR(IF(X67="","",ROUND(X67*$Y$11,2)),"") | Z67: =IFERROR(M67+S67+Y67,"") | AA67: =IFERROR(VLOOKUP(Z67,#REF!,2,TRUE),"") | AB67: {=IF(AA67="", "", _xlfn.IFS(AA67>=90, "A", AA67>=80, "B", AA67>=75, "C", AA67>=65, "D", AA67>=0, "E"))}
A68: 5 | K68: =IF(COUNT($F68:$J68)=0,"",SUM($F68:$J68)) | L68: =IFERROR(IF(K68="","",ROUND(K68/$K$11*100,2)),"") | M68: =IFERROR(IF(L68="","",ROUND(L68*$M$11,2)),"") | Q68: =IF(COUNT($N68:$P68)=0,"",SUM($N68:$P68)) | R68: =IFERROR(IF(Q68="","",ROUND(Q68/$Q$11*100,2)),"") | S68: =IFERROR(IF(R68="","",ROUND(R68*$S$11,2)),"") | W68: =IF(COUNT($T68:$V68)=0,"",SUM($T68:$V68)) | X68: =IFERROR(IF(W68="","",ROUND(W68/$W$11*100,2)),"") | Y68: =IFERROR(IF(X68="","",ROUND(X68*$Y$11,2)),"") | Z68: =IFERROR(M68+S68+Y68,"") | AA68: =IFERROR(VLOOKUP(Z68,#REF!,2,TRUE),"") | AB68: {=IF(AA68="", "", _xlfn.IFS(AA68>=90, "A", AA68>=80, "B", AA68>=75, "C", AA68>=65, "D", AA68>=0, "E"))}
A69: 6 | K69: =IF(COUNT($F69:$J69)=0,"",SUM($F69:$J69)) | L69: =IFERROR(IF(K69="","",ROUND(K69/$K$11*100,2)),"") | M69: =IFERROR(IF(L69="","",ROUND(L69*$M$11,2)),"") | Q69: =IF(COUNT($N69:$P69)=0,"",SUM($N69:$P69)) | R69: =IFERROR(IF(Q69="","",ROUND(Q69/$Q$11*100,2)),"") | S69: =IFERROR(IF(R69="","",ROUND(R69*$S$11,2)),"") | W69: =IF(COUNT($T69:$V69)=0,"",SUM($T69:$V69)) | X69: =IFERROR(IF(W69="","",ROUND(W69/$W$11*100,2)),"") | Y69: =IFERROR(IF(X69="","",ROUND(X69*$Y$11,2)),"") | Z69: =IFERROR(M69+S69+Y69,"") | AA69: =IFERROR(VLOOKUP(Z69,#REF!,2,TRUE),"") | AB69: {=IF(AA69="", "", _xlfn.IFS(AA69>=90, "A", AA69>=80, "B", AA69>=75, "C", AA69>=65, "D", AA69>=0, "E"))}
A70: 7 | K70: =IF(COUNT($F70:$J70)=0,"",SUM($F70:$J70)) | L70: =IFERROR(IF(K70="","",ROUND(K70/$K$11*100,2)),"") | M70: =IFERROR(IF(L70="","",ROUND(L70*$M$11,2)),"") | Q70: =IF(COUNT($N70:$P70)=0,"",SUM($N70:$P70)) | R70: =IFERROR(IF(Q70="","",ROUND(Q70/$Q$11*100,2)),"") | S70: =IFERROR(IF(R70="","",ROUND(R70*$S$11,2)),"") | W70: =IF(COUNT($T70:$V70)=0,"",SUM($T70:$V70)) | X70: =IFERROR(IF(W70="","",ROUND(W70/$W$11*100,2)),"") | Y70: =IFERROR(IF(X70="","",ROUND(X70*$Y$11,2)),"") | Z70: =IFERROR(M70+S70+Y70,"") | AA70: =IFERROR(VLOOKUP(Z70,#REF!,2,TRUE),"") | AB70: {=IF(AA70="", "", _xlfn.IFS(AA70>=90, "A", AA70>=80, "B", AA70>=75, "C", AA70>=65, "D", AA70>=0, "E"))}
A71: 8 | K71: =IF(COUNT($F71:$J71)=0,"",SUM($F71:$J71)) | L71: =IFERROR(IF(K71="","",ROUND(K71/$K$11*100,2)),"") | M71: =IFERROR(IF(L71="","",ROUND(L71*$M$11,2)),"") | Q71: =IF(COUNT($N71:$P71)=0,"",SUM($N71:$P71)) | R71: =IFERROR(IF(Q71="","",ROUND(Q71/$Q$11*100,2)),"") | S71: =IFERROR(IF(R71="","",ROUND(R71*$S$11,2)),"") | W71: =IF(COUNT($T71:$V71)=0,"",SUM($T71:$V71)) | X71: =IFERROR(IF(W71="","",ROUND(W71/$W$11*100,2)),"") | Y71: =IFERROR(IF(X71="","",ROUND(X71*$Y$11,2)),"") | Z71: =IFERROR(M71+S71+Y71,"") | AA71: =IFERROR(VLOOKUP(Z71,#REF!,2,TRUE),"") | AB71: {=IF(AA71="", "", _xlfn.IFS(AA71>=90, "A", AA71>=80, "B", AA71>=75, "C", AA71>=65, "D", AA71>=0, "E"))}
A72: 9 | K72: =IF(COUNT($F72:$J72)=0,"",SUM($F72:$J72)) | L72: =IFERROR(IF(K72="","",ROUND(K72/$K$11*100,2)),"") | M72: =IFERROR(IF(L72="","",ROUND(L72*$M$11,2)),"") | Q72: =IF(COUNT($N72:$P72)=0,"",SUM($N72:$P72)) | R72: =IFERROR(IF(Q72="","",ROUND(Q72/$Q$11*100,2)),"") | S72: =IFERROR(IF(R72="","",ROUND(R72*$S$11,2)),"") | W72: =IF(COUNT($T72:$V72)=0,"",SUM($T72:$V72)) | X72: =IFERROR(IF(W72="","",ROUND(W72/$W$11*100,2)),"") | Y72: =IFERROR(IF(X72="","",ROUND(X72*$Y$11,2)),"") | Z72: =IFERROR(M72+S72+Y72,"") | AA72: =IFERROR(VLOOKUP(Z72,#REF!,2,TRUE),"") | AB72: {=IF(AA72="", "", _xlfn.IFS(AA72>=90, "A", AA72>=80, "B", AA72>=75, "C", AA72>=65, "D", AA72>=0, "E"))}
A73: 10 | K73: =IF(COUNT($F73:$J73)=0,"",SUM($F73:$J73)) | L73: =IFERROR(IF(K73="","",ROUND(K73/$K$11*100,2)),"") | M73: =IFERROR(IF(L73="","",ROUND(L73*$M$11,2)),"") | Q73: =IF(COUNT($N73:$P73)=0,"",SUM($N73:$P73)) | R73: =IFERROR(IF(Q73="","",ROUND(Q73/$Q$11*100,2)),"") | S73: =IFERROR(IF(R73="","",ROUND(R73*$S$11,2)),"") | W73: =IF(COUNT($T73:$V73)=0,"",SUM($T73:$V73)) | X73: =IFERROR(IF(W73="","",ROUND(W73/$W$11*100,2)),"") | Y73: =IFERROR(IF(X73="","",ROUND(X73*$Y$11,2)),"") | Z73: =IFERROR(M73+S73+Y73,"") | AA73: =IFERROR(VLOOKUP(Z73,#REF!,2,TRUE),"") | AB73: {=IF(AA73="", "", _xlfn.IFS(AA73>=90, "A", AA73>=80, "B", AA73>=75, "C", AA73>=65, "D", AA73>=0, "E"))}
A74: 11 | K74: =IF(COUNT($F74:$J74)=0,"",SUM($F74:$J74)) | L74: =IFERROR(IF(K74="","",ROUND(K74/$K$11*100,2)),"") | M74: =IFERROR(IF(L74="","",ROUND(L74*$M$11,2)),"") | Q74: =IF(COUNT($N74:$P74)=0,"",SUM($N74:$P74)) | R74: =IFERROR(IF(Q74="","",ROUND(Q74/$Q$11*100,2)),"") | S74: =IFERROR(IF(R74="","",ROUND(R74*$S$11,2)),"") | W74: =IF(COUNT($T74:$V74)=0,"",SUM($T74:$V74)) | X74: =IFERROR(IF(W74="","",ROUND(W74/$W$11*100,2)),"") | Y74: =IFERROR(IF(X74="","",ROUND(X74*$Y$11,2)),"") | Z74: =IFERROR(M74+S74+Y74,"") | AA74: =IFERROR(VLOOKUP(Z74,#REF!,2,TRUE),"") | AB74: {=IF(AA74="", "", _xlfn.IFS(AA74>=90, "A", AA74>=80, "B", AA74>=75, "C", AA74>=65, "D", AA74>=0, "E"))}
A75: 12 | K75: =IF(COUNT($F75:$J75)=0,"",SUM($F75:$J75)) | L75: =IFERROR(IF(K75="","",ROUND(K75/$K$11*100,2)),"") | M75: =IFERROR(IF(L75="","",ROUND(L75*$M$11,2)),"") | Q75: =IF(COUNT($N75:$P75)=0,"",SUM($N75:$P75)) | R75: =IFERROR(IF(Q75="","",ROUND(Q75/$Q$11*100,2)),"") | S75: =IFERROR(IF(R75="","",ROUND(R75*$S$11,2)),"") | W75: =IF(COUNT($T75:$V75)=0,"",SUM($T75:$V75)) | X75: =IFERROR(IF(W75="","",ROUND(W75/$W$11*100,2)),"") | Y75: =IFERROR(IF(X75="","",ROUND(X75*$Y$11,2)),"") | Z75: =IFERROR(M75+S75+Y75,"") | AA75: =IFERROR(VLOOKUP(Z75,#REF!,2,TRUE),"") | AB75: {=IF(AA75="", "", _xlfn.IFS(AA75>=90, "A", AA75>=80, "B", AA75>=75, "C", AA75>=65, "D", AA75>=0, "E"))}
... A113: 50 | K113: =IF(COUNT($F113:$J113)=0,"",SUM($F113:$J113)) | L113: =IFERROR(IF(K113="","",ROUND(K113/$K$11*100,2)),"") | M113: =IFERROR(IF(L113="","",ROUND(L113*$M$11,2)),"") | Q113: =IF(COUNT($N113:$P113)=0,"",SUM($N113:$P113)) | R113: =IFERROR(IF(Q113="","",ROUND(Q113/$Q$11*100,2)),"") | S113: =IFERROR(IF(R113="","",ROUND(R113*$S$11,2)),"") | W113: =IF(COUNT($T113:$V113)=0,"",SUM($T113:$V113)) | X113: =IFERROR(IF(W113="","",ROUND(W113/$W$11*100,2)),"") | Y113: =IFERROR(IF(X113="","",ROUND(X113*$Y$11,2)),"") | Z113: =IFERROR(M113+S113+Y113,"") | AA113: =IFERROR(VLOOKUP(Z113,#REF!,2,TRUE),"") | AB113: {=IF(AA113="", "", _xlfn.IFS(AA113>=90, "A", AA113>=80, "B", AA113>=75, "C", AA113>=65, "D", AA113>=0, "E"))}

Sheet TERM 3
A1: Class Record
A3: (Pursuant to Deped Order 8 series of 2015)
F4: REGION | O4: DIVISION
F5: SCHOOL NAME | O5: SCHOOL ID | W5: SCHOOL YEAR
A7: THIRD TERM | F7: GRADE LEVEL AND SECTION | Q7: SUBJECT:
Q8: TEACHER:
A9: LEARNERS' NAMES | F9: WRITTEN/ ORAL WORKS (20%) | N9: PRODUCT/ PERFORMANCE TASKS (50%) | T9: SUMMATIVE TESTS/ TERM EXAMINATION (30%) | Z9: Initial Grade | AA9: Term Grade | AB9: Description
F10: 1 | G10: 2 | H10: 3 | I10: 4 | J10: 5 | K10: Total | L10: PS | M10: WS | N10: 1 | O10: 2 | P10: 3 | Q10: Total | R10: PS | S10: WS | T10: SA1 | U10: SA2 | V10: TE | W10: Total | X10: PS | Y10: WS
A11: HIGHEST POSSIBLE SCORE | K11: =IF(COUNT($F11:$J11)=0,"",SUM($F11:$J11)) | L11: 100 | M11: 0.2 | Q11: =IF(COUNT($N11:$P11)=0,"",SUM($N11:$P11)) | R11: 100 | S11: 0.5 | W11: =IF(COUNT($T11:$V11)=0,"",SUM($T11:$V11)) | X11: 100 | Y11: 0.3
A12: MALE
A13: 1 | K13: =IF(COUNT($F13:$J13)=0,"",SUM($F13:$J13)) | L13: =IFERROR(IF(K13="","",ROUND(K13/$K$11*100,2)),"") | M13: =IFERROR(IF(L13="","",ROUND(L13*$M$11,2)),"") | Q13: =IF(COUNT($N13:$P13)=0,"",SUM($N13:$P13)) | R13: =IFERROR(IF(Q13="","",ROUND(Q13/$Q$11*100,2)),"") | S13: =IFERROR(IF(R13="","",ROUND(R13*$S$11,2)),"") | W13: =IF(COUNT($T13:$V13)=0,"",SUM($T13:$V13)) | X13: =IFERROR(IF(W13="","",ROUND(W13/$W$11*100,2)),"") | Y13: =IFERROR(IF(X13="","",ROUND(X13*$Y$11,2)),"") | Z13: =IFERROR(M13+S13+Y13,"") | AA13: =IFERROR(VLOOKUP(Z13,#REF!,2,TRUE),"") | AB13: {=IF(AA13="", "", _xlfn.IFS(AA13>=90, "A", AA13>=80, "B", AA13>=75, "C", AA13>=65, "D", AA13>=0, "E"))}
A14: 2 | K14: =IF(COUNT($F14:$J14)=0,"",SUM($F14:$J14)) | L14: =IFERROR(IF(K14="","",ROUND(K14/$K$11*100,2)),"") | M14: =IFERROR(IF(L14="","",ROUND(L14*$M$11,2)),"") | Q14: =IF(COUNT($N14:$P14)=0,"",SUM($N14:$P14)) | R14: =IFERROR(IF(Q14="","",ROUND(Q14/$Q$11*100,2)),"") | S14: =IFERROR(IF(R14="","",ROUND(R14*$S$11,2)),"") | W14: =IF(COUNT($T14:$V14)=0,"",SUM($T14:$V14)) | X14: =IFERROR(IF(W14="","",ROUND(W14/$W$11*100,2)),"") | Y14: =IFERROR(IF(X14="","",ROUND(X14*$Y$11,2)),"") | Z14: =IFERROR(M14+S14+Y14,"") | AA14: =IFERROR(VLOOKUP(Z14,#REF!,2,TRUE),"") | AB14: {=IF(AA14="", "", _xlfn.IFS(AA14>=90, "A", AA14>=80, "B", AA14>=75, "C", AA14>=65, "D", AA14>=0, "E"))}
A15: 3 | K15: =IF(COUNT($F15:$J15)=0,"",SUM($F15:$J15)) | L15: =IFERROR(IF(K15="","",ROUND(K15/$K$11*100,2)),"") | M15: =IFERROR(IF(L15="","",ROUND(L15*$M$11,2)),"") | Q15: =IF(COUNT($N15:$P15)=0,"",SUM($N15:$P15)) | R15: =IFERROR(IF(Q15="","",ROUND(Q15/$Q$11*100,2)),"") | S15: =IFERROR(IF(R15="","",ROUND(R15*$S$11,2)),"") | W15: =IF(COUNT($T15:$V15)=0,"",SUM($T15:$V15)) | X15: =IFERROR(IF(W15="","",ROUND(W15/$W$11*100,2)),"") | Y15: =IFERROR(IF(X15="","",ROUND(X15*$Y$11,2)),"") | Z15: =IFERROR(M15+S15+Y15,"") | AA15: =IFERROR(VLOOKUP(Z15,#REF!,2,TRUE),"") | AB15: {=IF(AA15="", "", _xlfn.IFS(AA15>=90, "A", AA15>=80, "B", AA15>=75, "C", AA15>=65, "D", AA15>=0, "E"))}
A16: 4 | K16: =IF(COUNT($F16:$J16)=0,"",SUM($F16:$J16)) | L16: =IFERROR(IF(K16="","",ROUND(K16/$K$11*100,2)),"") | M16: =IFERROR(IF(L16="","",ROUND(L16*$M$11,2)),"") | Q16: =IF(COUNT($N16:$P16)=0,"",SUM($N16:$P16)) | R16: =IFERROR(IF(Q16="","",ROUND(Q16/$Q$11*100,2)),"") | S16: =IFERROR(IF(R16="","",ROUND(R16*$S$11,2)),"") | W16: =IF(COUNT($T16:$V16)=0,"",SUM($T16:$V16)) | X16: =IFERROR(IF(W16="","",ROUND(W16/$W$11*100,2)),"") | Y16: =IFERROR(IF(X16="","",ROUND(X16*$Y$11,2)),"") | Z16: =IFERROR(M16+S16+Y16,"") | AA16: =IFERROR(VLOOKUP(Z16,#REF!,2,TRUE),"") | AB16: {=IF(AA16="", "", _xlfn.IFS(AA16>=90, "A", AA16>=80, "B", AA16>=75, "C", AA16>=65, "D", AA16>=0, "E"))}
A17: 5 | K17: =IF(COUNT($F17:$J17)=0,"",SUM($F17:$J17)) | L17: =IFERROR(IF(K17="","",ROUND(K17/$K$11*100,2)),"") | M17: =IFERROR(IF(L17="","",ROUND(L17*$M$11,2)),"") | Q17: =IF(COUNT($N17:$P17)=0,"",SUM($N17:$P17)) | R17: =IFERROR(IF(Q17="","",ROUND(Q17/$Q$11*100,2)),"") | S17: =IFERROR(IF(R17="","",ROUND(R17*$S$11,2)),"") | W17: =IF(COUNT($T17:$V17)=0,"",SUM($T17:$V17)) | X17: =IFERROR(IF(W17="","",ROUND(W17/$W$11*100,2)),"") | Y17: =IFERROR(IF(X17="","",ROUND(X17*$Y$11,2)),"") | Z17: =IFERROR(M17+S17+Y17,"") | AA17: =IFERROR(VLOOKUP(Z17,#REF!,2,TRUE),"") | AB17: {=IF(AA17="", "", _xlfn.IFS(AA17>=90, "A", AA17>=80, "B", AA17>=75, "C", AA17>=65, "D", AA17>=0, "E"))}
A18: 6 | K18: =IF(COUNT($F18:$J18)=0,"",SUM($F18:$J18)) | L18: =IFERROR(IF(K18="","",ROUND(K18/$K$11*100,2)),"") | M18: =IFERROR(IF(L18="","",ROUND(L18*$M$11,2)),"") | Q18: =IF(COUNT($N18:$P18)=0,"",SUM($N18:$P18)) | R18: =IFERROR(IF(Q18="","",ROUND(Q18/$Q$11*100,2)),"") | S18: =IFERROR(IF(R18="","",ROUND(R18*$S$11,2)),"") | W18: =IF(COUNT($T18:$V18)=0,"",SUM($T18:$V18)) | X18: =IFERROR(IF(W18="","",ROUND(W18/$W$11*100,2)),"") | Y18: =IFERROR(IF(X18="","",ROUND(X18*$Y$11,2)),"") | Z18: =IFERROR(M18+S18+Y18,"") | AA18: =IFERROR(VLOOKUP(Z18,#REF!,2,TRUE),"") | AB18: {=IF(AA18="", "", _xlfn.IFS(AA18>=90, "A", AA18>=80, "B", AA18>=75, "C", AA18>=65, "D", AA18>=0, "E"))}
A19: 7 | K19: =IF(COUNT($F19:$J19)=0,"",SUM($F19:$J19)) | L19: =IFERROR(IF(K19="","",ROUND(K19/$K$11*100,2)),"") | M19: =IFERROR(IF(L19="","",ROUND(L19*$M$11,2)),"") | Q19: =IF(COUNT($N19:$P19)=0,"",SUM($N19:$P19)) | R19: =IFERROR(IF(Q19="","",ROUND(Q19/$Q$11*100,2)),"") | S19: =IFERROR(IF(R19="","",ROUND(R19*$S$11,2)),"") | W19: =IF(COUNT($T19:$V19)=0,"",SUM($T19:$V19)) | X19: =IFERROR(IF(W19="","",ROUND(W19/$W$11*100,2)),"") | Y19: =IFERROR(IF(X19="","",ROUND(X19*$Y$11,2)),"") | Z19: =IFERROR(M19+S19+Y19,"") | AA19: =IFERROR(VLOOKUP(Z19,#REF!,2,TRUE),"") | AB19: {=IF(AA19="", "", _xlfn.IFS(AA19>=90, "A", AA19>=80, "B", AA19>=75, "C", AA19>=65, "D", AA19>=0, "E"))}
A20: 8 | K20: =IF(COUNT($F20:$J20)=0,"",SUM($F20:$J20)) | L20: =IFERROR(IF(K20="","",ROUND(K20/$K$11*100,2)),"") | M20: =IFERROR(IF(L20="","",ROUND(L20*$M$11,2)),"") | Q20: =IF(COUNT($N20:$P20)=0,"",SUM($N20:$P20)) | R20: =IFERROR(IF(Q20="","",ROUND(Q20/$Q$11*100,2)),"") | S20: =IFERROR(IF(R20="","",ROUND(R20*$S$11,2)),"") | W20: =IF(COUNT($T20:$V20)=0,"",SUM($T20:$V20)) | X20: =IFERROR(IF(W20="","",ROUND(W20/$W$11*100,2)),"") | Y20: =IFERROR(IF(X20="","",ROUND(X20*$Y$11,2)),"") | Z20: =IFERROR(M20+S20+Y20,"") | AA20: =IFERROR(VLOOKUP(Z20,#REF!,2,TRUE),"") | AB20: {=IF(AA20="", "", _xlfn.IFS(AA20>=90, "A", AA20>=80, "B", AA20>=75, "C", AA20>=65, "D", AA20>=0, "E"))}
A21: 9 | K21: =IF(COUNT($F21:$J21)=0,"",SUM($F21:$J21)) | L21: =IFERROR(IF(K21="","",ROUND(K21/$K$11*100,2)),"") | M21: =IFERROR(IF(L21="","",ROUND(L21*$M$11,2)),"") | Q21: =IF(COUNT($N21:$P21)=0,"",SUM($N21:$P21)) | R21: =IFERROR(IF(Q21="","",ROUND(Q21/$Q$11*100,2)),"") | S21: =IFERROR(IF(R21="","",ROUND(R21*$S$11,2)),"") | W21: =IF(COUNT($T21:$V21)=0,"",SUM($T21:$V21)) | X21: =IFERROR(IF(W21="","",ROUND(W21/$W$11*100,2)),"") | Y21: =IFERROR(IF(X21="","",ROUND(X21*$Y$11,2)),"") | Z21: =IFERROR(M21+S21+Y21,"") | AA21: =IFERROR(VLOOKUP(Z21,#REF!,2,TRUE),"") | AB21: {=IF(AA21="", "", _xlfn.IFS(AA21>=90, "A", AA21>=80, "B", AA21>=75, "C", AA21>=65, "D", AA21>=0, "E"))}
A22: 10 | K22: =IF(COUNT($F22:$J22)=0,"",SUM($F22:$J22)) | L22: =IFERROR(IF(K22="","",ROUND(K22/$K$11*100,2)),"") | M22: =IFERROR(IF(L22="","",ROUND(L22*$M$11,2)),"") | Q22: =IF(COUNT($N22:$P22)=0,"",SUM($N22:$P22)) | R22: =IFERROR(IF(Q22="","",ROUND(Q22/$Q$11*100,2)),"") | S22: =IFERROR(IF(R22="","",ROUND(R22*$S$11,2)),"") | W22: =IF(COUNT($T22:$V22)=0,"",SUM($T22:$V22)) | X22: =IFERROR(IF(W22="","",ROUND(W22/$W$11*100,2)),"") | Y22: =IFERROR(IF(X22="","",ROUND(X22*$Y$11,2)),"") | Z22: =IFERROR(M22+S22+Y22,"") | AA22: =IFERROR(VLOOKUP(Z22,#REF!,2,TRUE),"") | AB22: {=IF(AA22="", "", _xlfn.IFS(AA22>=90, "A", AA22>=80, "B", AA22>=75, "C", AA22>=65, "D", AA22>=0, "E"))}
A23: 11 | K23: =IF(COUNT($F23:$J23)=0,"",SUM($F23:$J23)) | L23: =IFERROR(IF(K23="","",ROUND(K23/$K$11*100,2)),"") | M23: =IFERROR(IF(L23="","",ROUND(L23*$M$11,2)),"") | Q23: =IF(COUNT($N23:$P23)=0,"",SUM($N23:$P23)) | R23: =IFERROR(IF(Q23="","",ROUND(Q23/$Q$11*100,2)),"") | S23: =IFERROR(IF(R23="","",ROUND(R23*$S$11,2)),"") | W23: =IF(COUNT($T23:$V23)=0,"",SUM($T23:$V23)) | X23: =IFERROR(IF(W23="","",ROUND(W23/$W$11*100,2)),"") | Y23: =IFERROR(IF(X23="","",ROUND(X23*$Y$11,2)),"") | Z23: =IFERROR(M23+S23+Y23,"") | AA23: =IFERROR(VLOOKUP(Z23,#REF!,2,TRUE),"") | AB23: {=IF(AA23="", "", _xlfn.IFS(AA23>=90, "A", AA23>=80, "B", AA23>=75, "C", AA23>=65, "D", AA23>=0, "E"))}
A24: 12 | K24: =IF(COUNT($F24:$J24)=0,"",SUM($F24:$J24)) | L24: =IFERROR(IF(K24="","",ROUND(K24/$K$11*100,2)),"") | M24: =IFERROR(IF(L24="","",ROUND(L24*$M$11,2)),"") | Q24: =IF(COUNT($N24:$P24)=0,"",SUM($N24:$P24)) | R24: =IFERROR(IF(Q24="","",ROUND(Q24/$Q$11*100,2)),"") | S24: =IFERROR(IF(R24="","",ROUND(R24*$S$11,2)),"") | W24: =IF(COUNT($T24:$V24)=0,"",SUM($T24:$V24)) | X24: =IFERROR(IF(W24="","",ROUND(W24/$W$11*100,2)),"") | Y24: =IFERROR(IF(X24="","",ROUND(X24*$Y$11,2)),"") | Z24: =IFERROR(M24+S24+Y24,"") | AA24: =IFERROR(VLOOKUP(Z24,#REF!,2,TRUE),"") | AB24: {=IF(AA24="", "", _xlfn.IFS(AA24>=90, "A", AA24>=80, "B", AA24>=75, "C", AA24>=65, "D", AA24>=0, "E"))}
... A62: 50 | K62: =IF(COUNT($F62:$J62)=0,"",SUM($F62:$J62)) | L62: =IFERROR(IF(K62="","",ROUND(K62/$K$11*100,2)),"") | M62: =IFERROR(IF(L62="","",ROUND(L62*$M$11,2)),"") | Q62: =IF(COUNT($N62:$P62)=0,"",SUM($N62:$P62)) | R62: =IFERROR(IF(Q62="","",ROUND(Q62/$Q$11*100,2)),"") | S62: =IFERROR(IF(R62="","",ROUND(R62*$S$11,2)),"") | W62: =IF(COUNT($T62:$V62)=0,"",SUM($T62:$V62)) | X62: =IFERROR(IF(W62="","",ROUND(W62/$W$11*100,2)),"") | Y62: =IFERROR(IF(X62="","",ROUND(X62*$Y$11,2)),"") | Z62: =IFERROR(M62+S62+Y62,"") | AA62: =IFERROR(VLOOKUP(Z62,#REF!,2,TRUE),"") | AB62: {=IF(AA62="", "", _xlfn.IFS(AA62>=90, "A", AA62>=80, "B", AA62>=75, "C", AA62>=65, "D", AA62>=0, "E"))}
A63: FEMALE
A64: 1 | K64: =IF(COUNT($F64:$J64)=0,"",SUM($F64:$J64)) | L64: =IFERROR(IF(K64="","",ROUND(K64/$K$11*100,2)),"") | M64: =IFERROR(IF(L64="","",ROUND(L64*$M$11,2)),"") | Q64: =IF(COUNT($N64:$P64)=0,"",SUM($N64:$P64)) | R64: =IFERROR(IF(Q64="","",ROUND(Q64/$Q$11*100,2)),"") | S64: =IFERROR(IF(R64="","",ROUND(R64*$S$11,2)),"") | W64: =IF(COUNT($T64:$V64)=0,"",SUM($T64:$V64)) | X64: =IFERROR(IF(W64="","",ROUND(W64/$W$11*100,2)),"") | Y64: =IFERROR(IF(X64="","",ROUND(X64*$Y$11,2)),"") | Z64: =IFERROR(M64+S64+Y64,"") | AA64: =IFERROR(VLOOKUP(Z64,#REF!,2,TRUE),"") | AB64: {=IF(AA64="", "", _xlfn.IFS(AA64>=90, "A", AA64>=80, "B", AA64>=75, "C", AA64>=65, "D", AA64>=0, "E"))}
A65: 2 | K65: =IF(COUNT($F65:$J65)=0,"",SUM($F65:$J65)) | L65: =IFERROR(IF(K65="","",ROUND(K65/$K$11*100,2)),"") | M65: =IFERROR(IF(L65="","",ROUND(L65*$M$11,2)),"") | Q65: =IF(COUNT($N65:$P65)=0,"",SUM($N65:$P65)) | R65: =IFERROR(IF(Q65="","",ROUND(Q65/$Q$11*100,2)),"") | S65: =IFERROR(IF(R65="","",ROUND(R65*$S$11,2)),"") | W65: =IF(COUNT($T65:$V65)=0,"",SUM($T65:$V65)) | X65: =IFERROR(IF(W65="","",ROUND(W65/$W$11*100,2)),"") | Y65: =IFERROR(IF(X65="","",ROUND(X65*$Y$11,2)),"") | Z65: =IFERROR(M65+S65+Y65,"") | AA65: =IFERROR(VLOOKUP(Z65,#REF!,2,TRUE),"") | AB65: {=IF(AA65="", "", _xlfn.IFS(AA65>=90, "A", AA65>=80, "B", AA65>=75, "C", AA65>=65, "D", AA65>=0, "E"))}
A66: 3 | K66: =IF(COUNT($F66:$J66)=0,"",SUM($F66:$J66)) | L66: =IFERROR(IF(K66="","",ROUND(K66/$K$11*100,2)),"") | M66: =IFERROR(IF(L66="","",ROUND(L66*$M$11,2)),"") | Q66: =IF(COUNT($N66:$P66)=0,"",SUM($N66:$P66)) | R66: =IFERROR(IF(Q66="","",ROUND(Q66/$Q$11*100,2)),"") | S66: =IFERROR(IF(R66="","",ROUND(R66*$S$11,2)),"") | W66: =IF(COUNT($T66:$V66)=0,"",SUM($T66:$V66)) | X66: =IFERROR(IF(W66="","",ROUND(W66/$W$11*100,2)),"") | Y66: =IFERROR(IF(X66="","",ROUND(X66*$Y$11,2)),"") | Z66: =IFERROR(M66+S66+Y66,"") | AA66: =IFERROR(VLOOKUP(Z66,#REF!,2,TRUE),"") | AB66: {=IF(AA66="", "", _xlfn.IFS(AA66>=90, "A", AA66>=80, "B", AA66>=75, "C", AA66>=65, "D", AA66>=0, "E"))}
A67: 4 | K67: =IF(COUNT($F67:$J67)=0,"",SUM($F67:$J67)) | L67: =IFERROR(IF(K67="","",ROUND(K67/$K$11*100,2)),"") | M67: =IFERROR(IF(L67="","",ROUND(L67*$M$11,2)),"") | Q67: =IF(COUNT($N67:$P67)=0,"",SUM($N67:$P67)) | R67: =IFERROR(IF(Q67="","",ROUND(Q67/$Q$11*100,2)),"") | S67: =IFERROR(IF(R67="","",ROUND(R67*$S$11,2)),"") | W67: =IF(COUNT($T67:$V67)=0,"",SUM($T67:$V67)) | X67: =IFERROR(IF(W67="","",ROUND(W67/$W$11*100,2)),"") | Y67: =IFERROR(IF(X67="","",ROUND(X67*$Y$11,2)),"") | Z67: =IFERROR(M67+S67+Y67,"") | AA67: =IFERROR(VLOOKUP(Z67,#REF!,2,TRUE),"") | AB67: {=IF(AA67="", "", _xlfn.IFS(AA67>=90, "A", AA67>=80, "B", AA67>=75, "C", AA67>=65, "D", AA67>=0, "E"))}
A68: 5 | K68: =IF(COUNT($F68:$J68)=0,"",SUM($F68:$J68)) | L68: =IFERROR(IF(K68="","",ROUND(K68/$K$11*100,2)),"") | M68: =IFERROR(IF(L68="","",ROUND(L68*$M$11,2)),"") | Q68: =IF(COUNT($N68:$P68)=0,"",SUM($N68:$P68)) | R68: =IFERROR(IF(Q68="","",ROUND(Q68/$Q$11*100,2)),"") | S68: =IFERROR(IF(R68="","",ROUND(R68*$S$11,2)),"") | W68: =IF(COUNT($T68:$V68)=0,"",SUM($T68:$V68)) | X68: =IFERROR(IF(W68="","",ROUND(W68/$W$11*100,2)),"") | Y68: =IFERROR(IF(X68="","",ROUND(X68*$Y$11,2)),"") | Z68: =IFERROR(M68+S68+Y68,"") | AA68: =IFERROR(VLOOKUP(Z68,#REF!,2,TRUE),"") | AB68: {=IF(AA68="", "", _xlfn.IFS(AA68>=90, "A", AA68>=80, "B", AA68>=75, "C", AA68>=65, "D", AA68>=0, "E"))}
A69: 6 | K69: =IF(COUNT($F69:$J69)=0,"",SUM($F69:$J69)) | L69: =IFERROR(IF(K69="","",ROUND(K69/$K$11*100,2)),"") | M69: =IFERROR(IF(L69="","",ROUND(L69*$M$11,2)),"") | Q69: =IF(COUNT($N69:$P69)=0,"",SUM($N69:$P69)) | R69: =IFERROR(IF(Q69="","",ROUND(Q69/$Q$11*100,2)),"") | S69: =IFERROR(IF(R69="","",ROUND(R69*$S$11,2)),"") | W69: =IF(COUNT($T69:$V69)=0,"",SUM($T69:$V69)) | X69: =IFERROR(IF(W69="","",ROUND(W69/$W$11*100,2)),"") | Y69: =IFERROR(IF(X69="","",ROUND(X69*$Y$11,2)),"") | Z69: =IFERROR(M69+S69+Y69,"") | AA69: =IFERROR(VLOOKUP(Z69,#REF!,2,TRUE),"") | AB69: {=IF(AA69="", "", _xlfn.IFS(AA69>=90, "A", AA69>=80, "B", AA69>=75, "C", AA69>=65, "D", AA69>=0, "E"))}
A70: 7 | K70: =IF(COUNT($F70:$J70)=0,"",SUM($F70:$J70)) | L70: =IFERROR(IF(K70="","",ROUND(K70/$K$11*100,2)),"") | M70: =IFERROR(IF(L70="","",ROUND(L70*$M$11,2)),"") | Q70: =IF(COUNT($N70:$P70)=0,"",SUM($N70:$P70)) | R70: =IFERROR(IF(Q70="","",ROUND(Q70/$Q$11*100,2)),"") | S70: =IFERROR(IF(R70="","",ROUND(R70*$S$11,2)),"") | W70: =IF(COUNT($T70:$V70)=0,"",SUM($T70:$V70)) | X70: =IFERROR(IF(W70="","",ROUND(W70/$W$11*100,2)),"") | Y70: =IFERROR(IF(X70="","",ROUND(X70*$Y$11,2)),"") | Z70: =IFERROR(M70+S70+Y70,"") | AA70: =IFERROR(VLOOKUP(Z70,#REF!,2,TRUE),"") | AB70: {=IF(AA70="", "", _xlfn.IFS(AA70>=90, "A", AA70>=80, "B", AA70>=75, "C", AA70>=65, "D", AA70>=0, "E"))}
A71: 8 | K71: =IF(COUNT($F71:$J71)=0,"",SUM($F71:$J71)) | L71: =IFERROR(IF(K71="","",ROUND(K71/$K$11*100,2)),"") | M71: =IFERROR(IF(L71="","",ROUND(L71*$M$11,2)),"") | Q71: =IF(COUNT($N71:$P71)=0,"",SUM($N71:$P71)) | R71: =IFERROR(IF(Q71="","",ROUND(Q71/$Q$11*100,2)),"") | S71: =IFERROR(IF(R71="","",ROUND(R71*$S$11,2)),"") | W71: =IF(COUNT($T71:$V71)=0,"",SUM($T71:$V71)) | X71: =IFERROR(IF(W71="","",ROUND(W71/$W$11*100,2)),"") | Y71: =IFERROR(IF(X71="","",ROUND(X71*$Y$11,2)),"") | Z71: =IFERROR(M71+S71+Y71,"") | AA71: =IFERROR(VLOOKUP(Z71,#REF!,2,TRUE),"") | AB71: {=IF(AA71="", "", _xlfn.IFS(AA71>=90, "A", AA71>=80, "B", AA71>=75, "C", AA71>=65, "D", AA71>=0, "E"))}
A72: 9 | K72: =IF(COUNT($F72:$J72)=0,"",SUM($F72:$J72)) | L72: =IFERROR(IF(K72="","",ROUND(K72/$K$11*100,2)),"") | M72: =IFERROR(IF(L72="","",ROUND(L72*$M$11,2)),"") | Q72: =IF(COUNT($N72:$P72)=0,"",SUM($N72:$P72)) | R72: =IFERROR(IF(Q72="","",ROUND(Q72/$Q$11*100,2)),"") | S72: =IFERROR(IF(R72="","",ROUND(R72*$S$11,2)),"") | W72: =IF(COUNT($T72:$V72)=0,"",SUM($T72:$V72)) | X72: =IFERROR(IF(W72="","",ROUND(W72/$W$11*100,2)),"") | Y72: =IFERROR(IF(X72="","",ROUND(X72*$Y$11,2)),"") | Z72: =IFERROR(M72+S72+Y72,"") | AA72: =IFERROR(VLOOKUP(Z72,#REF!,2,TRUE),"") | AB72: {=IF(AA72="", "", _xlfn.IFS(AA72>=90, "A", AA72>=80, "B", AA72>=75, "C", AA72>=65, "D", AA72>=0, "E"))}
A73: 10 | K73: =IF(COUNT($F73:$J73)=0,"",SUM($F73:$J73)) | L73: =IFERROR(IF(K73="","",ROUND(K73/$K$11*100,2)),"") | M73: =IFERROR(IF(L73="","",ROUND(L73*$M$11,2)),"") | Q73: =IF(COUNT($N73:$P73)=0,"",SUM($N73:$P73)) | R73: =IFERROR(IF(Q73="","",ROUND(Q73/$Q$11*100,2)),"") | S73: =IFERROR(IF(R73="","",ROUND(R73*$S$11,2)),"") | W73: =IF(COUNT($T73:$V73)=0,"",SUM($T73:$V73)) | X73: =IFERROR(IF(W73="","",ROUND(W73/$W$11*100,2)),"") | Y73: =IFERROR(IF(X73="","",ROUND(X73*$Y$11,2)),"") | Z73: =IFERROR(M73+S73+Y73,"") | AA73: =IFERROR(VLOOKUP(Z73,#REF!,2,TRUE),"") | AB73: {=IF(AA73="", "", _xlfn.IFS(AA73>=90, "A", AA73>=80, "B", AA73>=75, "C", AA73>=65, "D", AA73>=0, "E"))}
A74: 11 | K74: =IF(COUNT($F74:$J74)=0,"",SUM($F74:$J74)) | L74: =IFERROR(IF(K74="","",ROUND(K74/$K$11*100,2)),"") | M74: =IFERROR(IF(L74="","",ROUND(L74*$M$11,2)),"") | Q74: =IF(COUNT($N74:$P74)=0,"",SUM($N74:$P74)) | R74: =IFERROR(IF(Q74="","",ROUND(Q74/$Q$11*100,2)),"") | S74: =IFERROR(IF(R74="","",ROUND(R74*$S$11,2)),"") | W74: =IF(COUNT($T74:$V74)=0,"",SUM($T74:$V74)) | X74: =IFERROR(IF(W74="","",ROUND(W74/$W$11*100,2)),"") | Y74: =IFERROR(IF(X74="","",ROUND(X74*$Y$11,2)),"") | Z74: =IFERROR(M74+S74+Y74,"") | AA74: =IFERROR(VLOOKUP(Z74,#REF!,2,TRUE),"") | AB74: {=IF(AA74="", "", _xlfn.IFS(AA74>=90, "A", AA74>=80, "B", AA74>=75, "C", AA74>=65, "D", AA74>=0, "E"))}
A75: 12 | K75: =IF(COUNT($F75:$J75)=0,"",SUM($F75:$J75)) | L75: =IFERROR(IF(K75="","",ROUND(K75/$K$11*100,2)),"") | M75: =IFERROR(IF(L75="","",ROUND(L75*$M$11,2)),"") | Q75: =IF(COUNT($N75:$P75)=0,"",SUM($N75:$P75)) | R75: =IFERROR(IF(Q75="","",ROUND(Q75/$Q$11*100,2)),"") | S75: =IFERROR(IF(R75="","",ROUND(R75*$S$11,2)),"") | W75: =IF(COUNT($T75:$V75)=0,"",SUM($T75:$V75)) | X75: =IFERROR(IF(W75="","",ROUND(W75/$W$11*100,2)),"") | Y75: =IFERROR(IF(X75="","",ROUND(X75*$Y$11,2)),"") | Z75: =IFERROR(M75+S75+Y75,"") | AA75: =IFERROR(VLOOKUP(Z75,#REF!,2,TRUE),"") | AB75: {=IF(AA75="", "", _xlfn.IFS(AA75>=90, "A", AA75>=80, "B", AA75>=75, "C", AA75>=65, "D", AA75>=0, "E"))}
... A113: 50 | K113: =IF(COUNT($F113:$J113)=0,"",SUM($F113:$J113)) | L113: =IFERROR(IF(K113="","",ROUND(K113/$K$11*100,2)),"") | M113: =IFERROR(IF(L113="","",ROUND(L113*$M$11,2)),"") | Q113: =IF(COUNT($N113:$P113)=0,"",SUM($N113:$P113)) | R113: =IFERROR(IF(Q113="","",ROUND(Q113/$Q$11*100,2)),"") | S113: =IFERROR(IF(R113="","",ROUND(R113*$S$11,2)),"") | W113: =IF(COUNT($T113:$V113)=0,"",SUM($T113:$V113)) | X113: =IFERROR(IF(W113="","",ROUND(W113/$W$11*100,2)),"") | Y113: =IFERROR(IF(X113="","",ROUND(X113*$Y$11,2)),"") | Z113: =IFERROR(M113+S113+Y113,"") | AA113: =IFERROR(VLOOKUP(Z113,#REF!,2,TRUE),"") | AB113: {=IF(AA113="", "", _xlfn.IFS(AA113>=90, "A", AA113>=80, "B", AA113>=75, "C", AA113>=65, "D", AA113>=0, "E"))}

Sheet SUMMARY
A1: Final Grades
B5: REGION | J5: DIVISION | Y5: SCHOOL ID
B6: SCHOOL NAME | Y6: SCHOOL YEAR
A9: LEARNERS' NAMES | F9: GRADE LEVEL & SECTION: | V9: SUBJECT:
V10: TEACHER:
F11: FIRST TERM | N11: SECOND TERM | V11: THIRD TERM | Z11: AVERAGE | AC11: REMARKS
A12: MALE
A13: 1 | H13: ='TERM 1'!AA13 | P13: ='TERM 2'!AA13 | V13: ='TERM 3'!AA13 | Z13: =IFERROR((H13+P13+V13)/3, "") | AC13: {=IF(XFD13="", "", _xlfn.IFS(XFD13>=90, "Advancing", XFD13>=80, "Benchmarking", XFD13>=75, "Connecting", XFD13>=65, "Developing", XFD13>=0, "Emerging"))} | XFD13: =Z13
A14: 2 | H14: ='TERM 1'!AA14 | P14: ='TERM 2'!AA14 | V14: ='TERM 3'!AA14 | Z14: =IFERROR((H14+P14+V14)/3, "") | AC14: {=IF(XFD14="", "", _xlfn.IFS(XFD14>=90, "Advancing", XFD14>=80, "Benchmarking", XFD14>=75, "Connecting", XFD14>=65, "Developing", XFD14>=0, "Emerging"))} | XFD14: =Z14
A15: 3 | H15: ='TERM 1'!AA15 | P15: ='TERM 2'!AA15 | V15: ='TERM 3'!AA15 | Z15: =IFERROR((H15+P15+V15)/3, "") | AC15: {=IF(XFD15="", "", _xlfn.IFS(XFD15>=90, "Advancing", XFD15>=80, "Benchmarking", XFD15>=75, "Connecting", XFD15>=65, "Developing", XFD15>=0, "Emerging"))} | XFD15: =Z15
A16: 4 | H16: ='TERM 1'!AA16 | P16: ='TERM 2'!AA16 | V16: ='TERM 3'!AA16 | Z16: =IFERROR((H16+P16+V16)/3, "") | AC16: {=IF(XFD16="", "", _xlfn.IFS(XFD16>=90, "Advancing", XFD16>=80, "Benchmarking", XFD16>=75, "Connecting", XFD16>=65, "Developing", XFD16>=0, "Emerging"))} | XFD16: =Z16
A17: 5 | H17: ='TERM 1'!AA17 | P17: ='TERM 2'!AA17 | V17: ='TERM 3'!AA17 | Z17: =IFERROR((H17+P17+V17)/3, "") | AC17: {=IF(XFD17="", "", _xlfn.IFS(XFD17>=90, "Advancing", XFD17>=80, "Benchmarking", XFD17>=75, "Connecting", XFD17>=65, "Developing", XFD17>=0, "Emerging"))} | XFD17: =Z17
A18: 6 | H18: ='TERM 1'!AA18 | P18: ='TERM 2'!AA18 | V18: ='TERM 3'!AA18 | Z18: =IFERROR((H18+P18+V18)/3, "") | AC18: {=IF(XFD18="", "", _xlfn.IFS(XFD18>=90, "Advancing", XFD18>=80, "Benchmarking", XFD18>=75, "Connecting", XFD18>=65, "Developing", XFD18>=0, "Emerging"))} | XFD18: =Z18
A19: 7 | H19: ='TERM 1'!AA19 | P19: ='TERM 2'!AA19 | V19: ='TERM 3'!AA19 | Z19: =IFERROR((H19+P19+V19)/3, "") | AC19: {=IF(XFD19="", "", _xlfn.IFS(XFD19>=90, "Advancing", XFD19>=80, "Benchmarking", XFD19>=75, "Connecting", XFD19>=65, "Developing", XFD19>=0, "Emerging"))} | XFD19: =Z19
A20: 8 | H20: ='TERM 1'!AA20 | P20: ='TERM 2'!AA20 | V20: ='TERM 3'!AA20 | Z20: =IFERROR((H20+P20+V20)/3, "") | AC20: {=IF(XFD20="", "", _xlfn.IFS(XFD20>=90, "Advancing", XFD20>=80, "Benchmarking", XFD20>=75, "Connecting", XFD20>=65, "Developing", XFD20>=0, "Emerging"))} | XFD20: =Z20
A21: 9 | H21: ='TERM 1'!AA21 | P21: ='TERM 2'!AA21 | V21: ='TERM 3'!AA21 | Z21: =IFERROR((H21+P21+V21)/3, "") | AC21: {=IF(XFD21="", "", _xlfn.IFS(XFD21>=90, "Advancing", XFD21>=80, "Benchmarking", XFD21>=75, "Connecting", XFD21>=65, "Developing", XFD21>=0, "Emerging"))} | XFD21: =Z21
A22: 10 | H22: ='TERM 1'!AA22 | P22: ='TERM 2'!AA22 | V22: ='TERM 3'!AA22 | Z22: =IFERROR((H22+P22+V22)/3, "") | AC22: {=IF(XFD22="", "", _xlfn.IFS(XFD22>=90, "Advancing", XFD22>=80, "Benchmarking", XFD22>=75, "Connecting", XFD22>=65, "Developing", XFD22>=0, "Emerging"))} | XFD22: =Z22
A23: 11 | H23: ='TERM 1'!AA23 | P23: ='TERM 2'!AA23 | V23: ='TERM 3'!AA23 | Z23: =IFERROR((H23+P23+V23)/3, "") | AC23: {=IF(XFD23="", "", _xlfn.IFS(XFD23>=90, "Advancing", XFD23>=80, "Benchmarking", XFD23>=75, "Connecting", XFD23>=65, "Developing", XFD23>=0, "Emerging"))} | XFD23: =Z23
A24: 12 | H24: ='TERM 1'!AA24 | P24: ='TERM 2'!AA24 | V24: ='TERM 3'!AA24 | Z24: =IFERROR((H24+P24+V24)/3, "") | AC24: {=IF(XFD24="", "", _xlfn.IFS(XFD24>=90, "Advancing", XFD24>=80, "Benchmarking", XFD24>=75, "Connecting", XFD24>=65, "Developing", XFD24>=0, "Emerging"))} | XFD24: =Z24
... A62: 50 | H62: ='TERM 1'!AA62 | P62: ='TERM 2'!AA62 | V62: ='TERM 3'!AA62 | Z62: =IFERROR((H62+P62+V62)/3, "") | AC62: {=IF(XFD62="", "", _xlfn.IFS(XFD62>=90, "Advancing", XFD62>=80, "Benchmarking", XFD62>=75, "Connecting", XFD62>=65, "Developing", XFD62>=0, "Emerging"))} | XFD62: =Z62
A63: FEMALE | F63: ='TERM 1'!AA63 -> 0 | XFD63: =Z63 -> 0
